Workbook
Name tfgld.dbcr: #REF!
Name tfgld.duac.pr: #REF!
Name tfgld.ptyp: #REF!

Sheet 资产负债表
A1: 资产负债表
H2: 表01
A3: =[1]报表封面!B2 -> 编制单位：长春英纳法富晟汽车天窗系统有限公司 | E3: =[1]报表封面!F8&[1]报表封面!G8&[1]报表封面!H8&[1]报表封面!I8 -> 2025年12月 | H3: 金额单位:元
A4: 资 产 | B4: 行次 | C4: 期末余额 | D4: 年初余额 | E4: 负债和所有者权益 | F4: 行次 | G4: 期末余额 | H4: 年初余额
A5: 流动资产： | B5: 1 | E5: 流动负债： | F5: 53
A6: 货币资金 | B6: 2 | C6: =C7+C8+C9 -> 9449826.6 | D6: =D7+D8+D9 -> 12279069 | E6: 短期借款 | F6: 54 | G6: =-SUMIF(科目余额表!$J:$J,资产负债表!E6,科目余额表!$W:$W) -> 23462093 | H6: 28000000
A7: 其中：现金 | B7: 3 | E7: 交易性金融负债 | F7: 55
A8: 银行存款 | B8: 4 | C8: =SUMIF(科目余额表!$J:$J,资产负债表!A8,科目余额表!$W:$W) -> 9449826.6 | D8: 12279069 | E8: 衍生金融负债 | F8: 56
A9: 其他货币资金 | B9: 5 | E9: 应付票据 | F9: 57
A10: 交易性金融资产 | B10: 6 | E10: 应付账款 | F10: 58 | G10: =-SUMIF(科目余额表!$J:$J,资产负债表!E10,科目余额表!$W:$W) -> 1.0720345e+08 | H10: 1.0788215e+08
A11: 衍生金融资产 | B11: 7 | E11: 预收款项 | F11: 59
A12: 应收票据 | B12: 8 | E12: 合同负债 | F12: 60
A13: 应收账款 | B13: 9 | C13: =SUMIF(科目余额表!$J:$J,资产负债表!A13,科目余额表!$W:$W) -> 15261058 | D13: 47581177 | E13: 应付职工薪酬 | F13: 61 | G13: =-SUMIF(科目余额表!$J:$J,资产负债表!E13,科目余额表!$W:$W) -> 1496794.8 | H13: 859487.6
A14: 应收款项融资 | B14: 10 | E14: 应交税费 | F14: 62 | G14: =-SUMIF(科目余额表!$J:$J,资产负债表!E14,科目余额表!$W:$W) -> -1543380.9 | H14: 141506.52
A15: 预付款项 | B15: 11 | C15: =SUMIF(科目余额表!$J:$J,资产负债表!A15,科目余额表!$W:$W) -> 306165.27 | D15: 404087.46 | E15: 其他应付款 | F15: 63 | G15: =-SUMIF(科目余额表!$J:$J,资产负债表!E15,科目余额表!$W:$W) -> 13858319
A16: 其他应收款 | B16: 12 | C16: =SUMIF(科目余额表!$J:$J,资产负债表!A16,科目余额表!$W:$W) -> 2175000 | D16: 500000 | E16: 持有待售负债 | F16: 64
A17: 存货 | B17: 13 | C17: =SUM(C18:C25) -> 3012430.2 | D17: =SUM(D18:D25) -> 4362130.5 | E17: 一年内到期的非流动负债 | F17: 65
A18: 其中：原材料 | B18: 14 | C18: =SUMIF(科目余额表!$J:$J,资产负债表!A18,科目余额表!$V:$V) -> 0 | E18: 其他流动负债 | F18: 66 | H18: 29223553
A19: 外购件 | B19: 15 | C19: =SUMIF(科目余额表!$J:$J,资产负债表!A19,科目余额表!$W:$W) -> 1420839.3 | D19: 2716684 | E19: 流动负债合计 | F19: 67 | G19: =SUM(G6:G18) -> 1.4447728e+08 | H19: =SUM(H6:H18) -> 1.661067e+08
A20: 在途材料 | B20: 16 | E20: 非流动负债： | F20: 68
A21: 自制半成品 | B21: 17 | E21: 长期借款 | F21: 69 | G21: =-SUMIF(科目余额表!$J:$J,资产负债表!E21,科目余额表!$W:$W) -> 7468903.6 | H21: 8375328
A22: 周转材料 | B22: 18 | C22: =SUMIF(科目余额表!$J:$J,资产负债表!A22,科目余额表!$W:$W) -> 0 | E22: 应付债券 | F22: 70
A23: 备件 | B23: 19 | E23: 租赁负债 | F23: 71
A24: 在制品 | B24: 20 | C24: =SUMIF(科目余额表!$J:$J,资产负债表!A24,科目余额表!$W:$W) -> 51071.29 | D24: 187304.53 | E24: 长期应付款 | F24: 72
A25: 库存商品 | B25: 21 | C25: =SUMIF(科目余额表!$J:$J,资产负债表!A25,科目余额表!$W:$W) -> 1540519.6 | D25: 1458142 | E25: 预计负债 | F25: 73
A26: 合同资产 | B26: 22 | E26: 递延收益 | F26: 74
A27: 持有待售资产 | B27: 23 | E27: 递延所得税负债 | F27: 75
A28: 一年内到期的非流动资产 | B28: 24 | E28: 其他非流动负债 | F28: 76
A29: 其他流动资产 | B29: 25 | C29: =SUMIF(科目余额表!$J:$J,资产负债表!A29,科目余额表!$W:$W) -> 11007941 | D29: 11320000 | E29: 非流动负债合计 | F29: 77 | G29: =SUM(G21:G28) -> 7468903.6 | H29: =SUM(H21:H28) -> 8375328
A30: 流动资产合计 | B30: 26 | C30: =SUM(C6,C10:C17,C26:C29) -> 41212421 | D30: =SUM(D6,D10:D17,D26:D29) -> 76446465 | E30: 负债合计 | F30: 78 | G30: =G19+G29 -> 1.5194618e+08 | H30: =H19+H29 -> 1.7448203e+08
A31: 非流动资产： | B31: 27 | F31: 79
A32: 债权投资 | B32: 28 | F32: 80
A33: 其他债权投资 | B33: 29 | F33: 81
A34: 长期应收款 | B34: 30 | F34: 82
A35: 长期股权投资 | B35: 31 | F35: 83
A36: 其他权益工具投资 | B36: 32 | F36: 84
A37: 其他非流动金融资产 | B37: 33 | F37: 85
A38: 投资性房地产 | B38: 34 | F38: 86
A39: 固定资产原价 | B39: 35 | C39: =SUMIF(科目余额表!$J:$J,资产负债表!A39,科目余额表!$W:$W) -> 44044785 | D39: 35955450 | F39: 87
A40: 减：累计折旧 | B40: 36 | C40: =-SUMIF(科目余额表!$J:$J,资产负债表!A40,科目余额表!$W:$W) -> 17865027 | D40: 11473339 | F40: 88
...

Sheet 利润表
A1: 利润表
J2: 表02
A3: =[1]报表封面!B2 -> 编制单位：长春英纳法富晟汽车天窗系统有限公司 | E3: =[1]报表封面!F8&[1]报表封面!G8&[1]报表封面!H8&[1]报表封面!I8 -> 2025年12月 | J3: 金额单位:元
A4: 项 目 | B4: 行次 | C4: 本月数 | D4: 本年累计数 | E4: 上年同期累计数 | F4: 项 目 | G4: 行次 | H4: 本 月 数 | I4: 本年累计数 | J4: 上年同期累计数
A5: 一、营业收入 | B5: 1 | C5: =C6+C7 -> 10733666 | D5: =D6+D7 -> 71116643 | E5: =E6+E7 -> 0 | F5: 六、综合收益总额 | G5: 31 | H5: =C31+C34 -> -236892.85 | I5: =D31+D34 -> -17536883 | J5: =E31+E34 -> 0
A6: 其中：主营业务收入 | B6: 2 | C6: =SUMIF(科目余额表!$J:$J,利润表!A6,科目余额表!W:W) -> 7863070 | D6: =SUMIF(科目余额表!$J:$J,利润表!A6,科目余额表!X:X) -> 66261622 | F6: 归属于少数股东的综合损益总额★ | G6: 32 | H6: =C32 -> 0 | I6: =D32 -> 0 | J6: =E32 -> 0
A7: 其他业务收入 | B7: 3 | C7: =SUMIF(科目余额表!$J:$J,利润表!A7,科目余额表!W:W) -> 2870596.4 | D7: =SUMIF(科目余额表!$J:$J,利润表!A7,科目余额表!X:X) -> 4855021.1 | F7: 归属于母公司所有者的综合收益总额 | G7: 33 | H7: =H5-H6 -> -236892.85 | I7: =I5-I6 -> -17536883 | J7: =J5-J6 -> 0
A8: 减：营业成本 | B8: 4 | C8: =C9+C10 -> 9207479.4 | D8: =D9+D10 -> 75771376 | E8: =E9+E10 -> 0 | F8: 七、每股收益 | G8: 34
A9: 其中：主营业务成本 | B9: 5 | C9: =-SUMIF(科目余额表!$J:$J,利润表!A9,科目余额表!W:W) -> 6342841.6 | D9: =-SUMIF(科目余额表!$J:$J,利润表!A9,科目余额表!X:X) -> 70934238 | F9: 补充资料 | G9: 35
A10: 其他业务成本 | B10: 6 | C10: =-SUMIF(科目余额表!$J:$J,利润表!A10,科目余额表!W:W) -> 2864637.7 | D10: =-SUMIF(科目余额表!$J:$J,利润表!A10,科目余额表!X:X) -> 4837137.7 | G10: 36
A11: 税金及附加 | B11: 7 | C11: =-SUMIF(科目余额表!$J:$J,利润表!A11,科目余额表!W:W) -> 47600.75 | D11: =-SUMIF(科目余额表!$J:$J,利润表!A11,科目余额表!X:X) -> 75125.59 | G11: 37
A12: 销售费用 | B12: 8 | C12: =-SUMIF(科目余额表!$J:$J,利润表!A12,科目余额表!W:W) -> 0 | D12: =-SUMIF(科目余额表!$J:$J,利润表!A12,科目余额表!X:X) -> 0 | F12: 一、营业外收入小计 | G12: 38 | H12: =SUM(H13:H21) -> 0 | I12: =SUM(I13:I21) -> 0.83 | J12: =SUM(J13:J21) -> 0
A13: 管理费用 | B13: 9 | C13: =-SUMIF(科目余额表!$J:$J,利润表!A13,科目余额表!W:W) -> 1000804.7 | D13: =-SUMIF(科目余额表!$J:$J,利润表!A13,科目余额表!X:X) -> 12320863 | F13: 罚款收入 | G13: 39
A14: 研发费用 | B14: 10 | C14: =-SUMIF(科目余额表!$J:$J,利润表!A14,科目余额表!W:W) -> 272923.58 | D14: =-SUMIF(科目余额表!$J:$J,利润表!A14,科目余额表!X:X) -> 4970224.7 | F14: 债务重组利得 | G14: 40
A15: 财务费用 | B15: 11 | C15: =-SUMIF(科目余额表!$J:$J,利润表!A15,科目余额表!W:W) -> 62191.13 | D15: =-SUMIF(科目余额表!$J:$J,利润表!A15,科目余额表!X:X) -> 906746.54 | F15: 政府补贴 | G15: 41
A16: 其中：利息费用 | B16: 12 | C16: =-科目余额表!W588 -> 83222.39 | D16: =-科目余额表!X588 -> 947883.05 | F16: 固定资产盘盈 | G16: 42
A17: 利息收入 | B17: 13 | C17: =-科目余额表!W587 -> -7360.49 | D17: =-科目余额表!X587 -> -54828.44 | F17: 其他 | G17: 43 | I17: 0.83
A18: 加：其他收益（损失以“－”号填） | B18: 14 | C18: =-SUMIF(科目余额表!$J:$J,利润表!A18,科目余额表!W:W) -> 0 | D18: =SUMIF(科目余额表!$J:$J,利润表!A18,科目余额表!X:X) -> 3705.34 | G18: 44
A19: 投资收益（损失以“－”号填） | B19: 15 | C19: =-SUMIF(科目余额表!$J:$J,利润表!A19,科目余额表!W:W) -> 0 | D19: =-SUMIF(科目余额表!$J:$J,利润表!A19,科目余额表!X:X) -> 0 | G19: 45
A20: 其中：对联营企业和合营企业的投资收益 | B20: 16 | G20: 46
A21: 以摊余成本计量的金融资产终止确认收益 | B21: 17 | G21: 47
A22: 公允价值变动收益（损失以“－”号填） | B22: 18 | F22: 二、营业外支出小计 | G22: 48 | H22: =SUM(H23:H29) -> 0 | I22: =SUM(I23:I29) -> 0 | J22: =SUM(J23:J29) -> 0
A23: 信用减值损失（损失以“－”号填） | B23: 19 | F23: 固定资产盘亏 | G23: 49
A24: 资产减值损失（损失以“－”号填） | B24: 20 | C24: =SUMIF(科目余额表!$J:$J,利润表!A24,科目余额表!W:W) -> -133777.54 | D24: =SUMIF(科目余额表!$J:$J,利润表!A24,科目余额表!X:X) -> -133777.54 | F24: 非流动资产毁损报废损失 | G24: 50
A25: 资产处置收益（损失以“－”号填） | B25: 21 | C25: =-SUMIF(科目余额表!$J:$J,利润表!A25,科目余额表!W:W) -> 0 | D25: =-SUMIF(科目余额表!$J:$J,利润表!A25,科目余额表!X:X) -> 0 | F25: 罚款/赔偿/违约金 | G25: 51
A26: 二、营业利润（亏损以“－”号填列） | B26: 22 | C26: =C5-C8-C11-C12-C13-C14-C15+C18+C19+C22+C23+C24+C25 -> 8889.32 | D26: =D5-D8-D11-D12-D13-D14-D15+D18+D19+D22+D23+D24+D25 -> -23057765 | E26: =E5-E8-E11-E12-E13-E14-E15+E18+E19+E22+E23+E24+E25 -> 0 | F26: 非常损失 | G26: 52
A27: 加：营业外收入 | B27: 23 | C27: =-SUMIF(科目余额表!$J:$J,利润表!A27,科目余额表!W:W) -> 0 | D27: =SUMIF(科目余额表!$J:$J,利润表!A27,科目余额表!X:X) -> 0.83 | F27: 债务重组损失 | G27: 53
A28: 减：营业外支出 | B28: 24 | C28: =-SUMIF(科目余额表!$J:$J,利润表!A28,科目余额表!W:W) -> 0 | D28: =-SUMIF(科目余额表!$J:$J,利润表!A28,科目余额表!X:X) -> 0 | F28: 公益性捐助 | G28: 54
A29: 三、利润总额（亏损总额以“－”号填列） | B29: 25 | C29: =C26+C27-C28 -> 8889.32 | D29: =D26+D27-D28 -> -23057764 | E29: =E26+E27-E28 -> 0 | F29: 其他 | G29: 55
A30: 减：所得税费用 | B30: 26 | C30: =-SUMIF(科目余额表!$J:$J,利润表!A30,科目余额表!W:W) -> 245782.17 | D30: =-SUMIF(科目余额表!$J:$J,利润表!A30,科目余额表!X:X) -> -5520881.3 | G30: 56
A31: 四、净利润（净亏损以“－”号填） | B31: 27 | C31: =C29-C30 -> -236892.85 | D31: =D29-D30 -> -17536883 | E31: =E29-E30 -> 0 | G31: 57
A32: 少数股东损益★ | B32: 28 | G32: 58
A33: 归属于母公司所有者的净利润 | B33: 29 | C33: =C31-C32 -> -236892.85 | D33: =D31-D32 -> -17536883 | E33: =E31-E32 -> 0 | G33: 59
A34: 五、其他综合收益的税后净额 | B34: 30 | G34: 60
A35: 注：标★的项目为合并报表专用项目。
A36: 单位负责人： | E36: 财务负责人： | I36: 制表人：

Sheet 现金流量表
A1: 现金流量表
A2: 表03
A3: =[1]报表封面!B2 -> 编制单位：长春英纳法富晟汽车天窗系统有限公司 | B3: =利润表!E3 -> 2025年12月 | D3: 金额单位:元
A4: 项目 | B4: 行次 | C4: 合计
C5: 本月数 | D5: 累计数
A6: 一、经营活动产生的现金流量 | B6: 1
A7: 销售商品、提供劳务收到的现金 | B7: 2 | C7: =16211077.34-2946420.91 -> 13264656 | D7: =13264656.43+69589058.01 -> 82853714
A8: 收到的税费返还 | B8: 3
A9: 收到的其他与经营活动有关的现金 | B9: 4 | C9: 8560.49 | D9: =8560.49+67834.76 -> 76395.25
A10: 现金流入小计 | B10: 5 | C10: =ROUND(SUM(C7:C9),2) -> 13273217 | D10: =ROUND(SUM(D7:D9),2) -> 82930110
A11: 购买商品、接收劳务支付的现金 | B11: 6 | C11: =-1093127.64+4193296.84999999 -> 3100169.2 | D11: =3100169.21+46151771.7 -> 49251941
A12: 支付给职工以及为职工支付的现金 | B12: 7 | C12: 1215049.9 | D12: =1215049.9+10099480.01 -> 11314530
A13: 支付的各项税费 | B13: 8 | C13: 42342.68 | D13: =42342.68+695055.81 -> 737398.49
A14: 支付的其他与经营活动有关的现金 | B14: 9 | C14: =-1853293.27+3039546.87 -> 1186253.6 | D14: =1186253.6+12753028.42 -> 13939282
A15: 现金流出小计 | B15: 10 | C15: =ROUND(SUM(C11:C14),2) -> 5543815.4 | D15: =ROUND(SUM(D11:D14),2) -> 75243151
A16: 经营活动产生的现金流量净额 | B16: 11 | C16: =ROUND(C10-C15,2) -> 7729401.5 | D16: =ROUND(D10-D15,2) -> 7686958.4
A17: 二、投资活动产生的现金流量 | B17: 12
A18: 收回投资所收到的现金 | B18: 13
A19: 取得投资收益所收到的现金 | B19: 14
A20: 处置固定资产、无形资产和其他长期资产收回现金净额 | B20: 15
A21: 处置子公司及其他营业单位收到的现金净额 | B21: 16
A22: 收到的其他与投资活动有关的现金 | B22: 17
A23: 现金流入小计 | B23: 18 | C23: =ROUND(SUM(C18:C22),2) -> 0 | D23: =ROUND(SUM(D18:D22),2) -> 0
A24: 购建固定资产、无形资产和其他长期资产所支付的现金 | B24: 19 | C24: 66715.2 | D24: =66715.2+4071352.74 -> 4138067.9
A25: 投资所支付的现金 | B25: 20
A26: 取得子公司及其他营业单位支付的现金净额 | B26: 21
A27: 支付的其他与投资活动有关的现金 | B27: 22
A28: 现金流出小计 | B28: 23 | C28: =ROUND(SUM(C24:C27),2) -> 66715.2 | D28: =ROUND(SUM(D24:D27),2) -> 4138067.9
A29: 投资活动产生的现金流量净额 | B29: 24 | C29: =ROUND(C23-C28,2) -> -66715.2 | D29: =ROUND(D23-D28,2) -> -4138067.9
A30: 三、筹资活动产生的现金流量 | B30: 25
A31: 吸收投资所收到的现金 | B31: 26
A32: 取得借款所收到的现金 | B32: 27 | C32: 1489158.1 | D32: =1489158.08+37609081.52 -> 39098240
A33: 收到的其他与筹资活动有关的现金 | B33: 28
A34: 现金流入小计 | B34: 29 | C34: =ROUND(SUM(C31,C32:C33),2) -> 1489158.1 | D34: =ROUND(SUM(D31,D32:D33),2) -> 39098240
A35: 偿还债务所支付的现金 | B35: 30 | C35: 1903960.1 | D35: =1903960.12+42628610.41 -> 44532571
A36: 分配股利、利润或偿付利息支付的现金 | B36: 31 | C36: 220024.42 | D36: =220024.42+723777.72 -> 943802.14
A37: 支付的其他与筹资活动有关的现金 | B37: 32
A38: 现金流出小计 | B38: 33 | C38: =ROUND(SUM(C35:C36,C37),2) -> 2123984.5 | D38: =ROUND(SUM(D35:D36,D37),2) -> 45476373
A39: 筹资活动产生的现金流量净额 | B39: 34 | C39: =ROUND(C34-C38,2) -> -634826.46 | D39: =ROUND(D34-D38,2) -> -6378133.1
A40: 四、汇率变动对现金及现金等价物的影响 | B40: 35
...

Sheet 现金流量表补充资料
A1: 现金流量表附注
D2: 表05
A3: =[1]报表封面!B2 -> 编制单位：长春英纳法富晟汽车天窗系统有限公司 | B3: =利润表!E3 -> 2025年12月 | D3: 金额单位：元
A4: 补充资料 | B4: 行次 | C4: 本月数 | D4: 累计数
A5: 一、将净利润调节为经营活动的内部现金流量 | B5: 1 | C5: ———— | D5: ————
A6: 净利润 | B6: 2 | C6: -236892.85 | D6: -17536883
A7: 加:资产减值准备 | B7: 3
A8: 固定资产折旧 | B8: 4 | C8: -570535.47 | D8: -6919260.2
A9: 投资性房地产折旧(摊销) | B9: 5
A10: 使用权资产折旧 | B10: 6
A11: 无形资产摊销 | B11: 7 | C11: -262442.09 | D11: -4962968.2
A12: 长期待摊费用摊销 | B12: 8 | C12: -382101.3 | D12: -4585215.6
A13: 处置固定资产、无形资产和其他长期资产的损失(收益以“-”号填列) | B13: 9
A14: 固定资产报废损失(收益以“-”号填列) | B14: 10
A15: 公允价值变动损失(收益以“-”号填列) | B15: 11
A16: 财务费用(收益以“-”号填列) | B16: 12 | C16: 62191.13 | D16: 906746.54
A17: 投资损失(收益以“-”号填列) | B17: 13
A18: 递延所得税资产减少(增加以“-”号填列) | B18: 14
A19: 递延所得税负债增加(减少以“-”号填列) | B19: 15
A20: 存货的减少(增加以“-”号填列) | B20: 16 | C20: -512794.67 | D20: 1215922.8
A21: 经营性应收项目的减少(增加以“-”号填列)(含应收票据) | B21: 17 | C21: 4075813.5 | D21: 32320120
A22: 经营性应付项目的增加(减少以“-”号填列) | B22: 18 | C22: -1126870.5 | D22: -5728398.4
A23: 其他 | B23: 19 | C23: 6683033.7 | D23: 12976895
A24: 经营活动产生的现金流量净额 | B24: 20 | C24: =SUM(C6:C23) -> 7729401.5 | D24: =SUM(D6:D23) -> 7686958.4
A26: 单位负责人： 财务负责人： | D26: 制表人：

Sheet 科目余额表
B2: =[1]报表封面!D2 -> 0
B3: 科目余额表 | H3: 表06
H4: 单位：元
B5: 账户代码 | C5: 账户名称 | D5: 期初余额 | E5: 期间活动 | F5: 期末余额 | G5: 汇总到 | H5: 类型 | J5: 提示：J列以后未锁定，企业可以编辑 | K5: Last | L5: Jan | M5: Feb | N5: Mar | O5: Apr | P5: May | Q5: Jun | R5: Jul | S5: Aug | T5: Sep | U5: Oct | V5: Nov | W5: Dec | X5: Total
B6: 10000 | C6: 现金-人民币 | D6: 0 | E6: 0 | F6: =D6+E6 -> 0 | G6: 现金 | H6: B | J6: 其中：现金 | L6: =IFERROR(SUMIF(data!$E:$E,科目余额表!$B6,data!H:H),0) -> 0 | M6: =IFERROR(SUMIF(data!$E:$E,科目余额表!$B6,data!I:I),0) -> 0 | N6: =IFERROR(SUMIF(data!$E:$E,科目余额表!$B6,data!J:J),0) -> 0 | O6: =IFERROR(SUMIF(data!$E:$E,科目余额表!$B6,data!K:K),0) -> 0 | P6: =IFERROR(SUMIF(data!$E:$E,科目余额表!$B6,data!L:L),0) -> 0 | Q6: =IFERROR(SUMIF(data!$E:$E,科目余额表!$B6,data!M:M),0) -> 0 | R6: =IFERROR(SUMIF(data!$E:$E,科目余额表!$B6,data!N:N),0) -> 0 | S6: =IFERROR(SUMIF(data!$E:$E,科目余额表!$B6,data!O:O),0) -> 0 | T6: =IFERROR(SUMIF(data!$E:$E,科目余额表!$B6,data!P:P),0) -> 0 | U6: =IFERROR(SUMIF(data!$E:$E,科目余额表!$B6,data!Q:Q),0) -> 0 | V6: =IFERROR(SUMIF(data!$E:$E,科目余额表!$B6,data!R:R),0) -> 0 | W6: =IFERROR(SUMIF(data!$E:$E,科目余额表!$B6,data!S:S),0) -> 0
B7: 10001 | C7: 现金-美元 | D7: 0 | E7: 0 | F7: =D7+E7 -> 0 | G7: 现金 | H7: B | J7: 其中：现金 | L7: =IFERROR(SUMIF(data!$E:$E,科目余额表!$B7,data!H:H),0) -> 0 | M7: =IFERROR(SUMIF(data!$E:$E,科目余额表!$B7,data!I:I),0) -> 0 | N7: =IFERROR(SUMIF(data!$E:$E,科目余额表!$B7,data!J:J),0) -> 0 | O7: =IFERROR(SUMIF(data!$E:$E,科目余额表!$B7,data!K:K),0) -> 0 | P7: =IFERROR(SUMIF(data!$E:$E,科目余额表!$B7,data!L:L),0) -> 0 | Q7: =IFERROR(SUMIF(data!$E:$E,科目余额表!$B7,data!M:M),0) -> 0 | R7: =IFERROR(SUMIF(data!$E:$E,科目余额表!$B7,data!N:N),0) -> 0 | S7: =IFERROR(SUMIF(data!$E:$E,科目余额表!$B7,data!O:O),0) -> 0 | T7: =IFERROR(SUMIF(data!$E:$E,科目余额表!$B7,data!P:P),0) -> 0 | U7: =IFERROR(SUMIF(data!$E:$E,科目余额表!$B7,data!Q:Q),0) -> 0 | V7: =IFERROR(SUMIF(data!$E:$E,科目余额表!$B7,data!R:R),0) -> 0 | W7: =IFERROR(SUMIF(data!$E:$E,科目余额表!$B7,data!S:S),0) -> 0
B8: 10002 | C8: 现金-日元 | D8: 0 | E8: 0 | F8: =D8+E8 -> 0 | G8: 现金 | H8: B | J8: 其中：现金 | L8: =IFERROR(SUMIF(data!$E:$E,科目余额表!$B8,data!H:H),0) -> 0 | M8: =IFERROR(SUMIF(data!$E:$E,科目余额表!$B8,data!I:I),0) -> 0 | N8: =IFERROR(SUMIF(data!$E:$E,科目余额表!$B8,data!J:J),0) -> 0 | O8: =IFERROR(SUMIF(data!$E:$E,科目余额表!$B8,data!K:K),0) -> 0 | P8: =IFERROR(SUMIF(data!$E:$E,科目余额表!$B8,data!L:L),0) -> 0 | Q8: =IFERROR(SUMIF(data!$E:$E,科目余额表!$B8,data!M:M),0) -> 0 | R8: =IFERROR(SUMIF(data!$E:$E,科目余额表!$B8,data!N:N),0) -> 0 | S8: =IFERROR(SUMIF(data!$E:$E,科目余额表!$B8,data!O:O),0) -> 0 | T8: =IFERROR(SUMIF(data!$E:$E,科目余额表!$B8,data!P:P),0) -> 0 | U8: =IFERROR(SUMIF(data!$E:$E,科目余额表!$B8,data!Q:Q),0) -> 0 | V8: =IFERROR(SUMIF(data!$E:$E,科目余额表!$B8,data!R:R),0) -> 0 | W8: =IFERROR(SUMIF(data!$E:$E,科目余额表!$B8,data!S:S),0) -> 0
B9: 10003 | C9: 现金-韩元 | D9: 0 | E9: 0 | F9: =D9+E9 -> 0 | G9: 现金 | H9: B | J9: 其中：现金 | L9: =IFERROR(SUMIF(data!$E:$E,科目余额表!$B9,data!H:H),0) -> 0 | M9: =IFERROR(SUMIF(data!$E:$E,科目余额表!$B9,data!I:I),0) -> 0 | N9: =IFERROR(SUMIF(data!$E:$E,科目余额表!$B9,data!J:J),0) -> 0 | O9: =IFERROR(SUMIF(data!$E:$E,科目余额表!$B9,data!K:K),0) -> 0 | P9: =IFERROR(SUMIF(data!$E:$E,科目余额表!$B9,data!L:L),0) -> 0 | Q9: =IFERROR(SUMIF(data!$E:$E,科目余额表!$B9,data!M:M),0) -> 0 | R9: =IFERROR(SUMIF(data!$E:$E,科目余额表!$B9,data!N:N),0) -> 0 | S9: =IFERROR(SUMIF(data!$E:$E,科目余额表!$B9,data!O:O),0) -> 0 | T9: =IFERROR(SUMIF(data!$E:$E,科目余额表!$B9,data!P:P),0) -> 0 | U9: =IFERROR(SUMIF(data!$E:$E,科目余额表!$B9,data!Q:Q),0) -> 0 | V9: =IFERROR(SUMIF(data!$E:$E,科目余额表!$B9,data!R:R),0) -> 0 | W9: =IFERROR(SUMIF(data!$E:$E,科目余额表!$B9,data!S:S),0) -> 0
B10: 10004 | C10: 现金-备用1 | D10: 0 | E10: 0 | F10: =D10+E10 -> 0 | G10: 现金 | H10: B | J10: 其中：现金 | L10: =IFERROR(SUMIF(data!$E:$E,科目余额表!$B10,data!H:H),0) -> 0 | M10: =IFERROR(SUMIF(data!$E:$E,科目余额表!$B10,data!I:I),0) -> 0 | N10: =IFERROR(SUMIF(data!$E:$E,科目余额表!$B10,data!J:J),0) -> 0 | O10: =IFERROR(SUMIF(data!$E:$E,科目余额表!$B10,data!K:K),0) -> 0 | P10: =IFERROR(SUMIF(data!$E:$E,科目余额表!$B10,data!L:L),0) -> 0 | Q10: =IFERROR(SUMIF(data!$E:$E,科目余额表!$B10,data!M:M),0) -> 0 | R10: =IFERROR(SUMIF(data!$E:$E,科目余额表!$B10,data!N:N),0) -> 0 | S10: =IFERROR(SUMIF(data!$E:$E,科目余额表!$B10,data!O:O),0) -> 0 | T10: =IFERROR(SUMIF(data!$E:$E,科目余额表!$B10,data!P:P),0) -> 0 | U10: =IFERROR(SUMIF(data!$E:$E,科目余额表!$B10,data!Q:Q),0) -> 0 | V10: =IFERROR(SUMIF(data!$E:$E,科目余额表!$B10,data!R:R),0) -> 0 | W10: =IFERROR(SUMIF(data!$E:$E,科目余额表!$B10,data!S:S),0) -> 0
B11: 10005 | C11: 现金-备用2 | D11: 0 | E11: 0 | F11: =D11+E11 -> 0 | G11: 现金 | H11: B | J11: 其中：现金 | L11: =IFERROR(SUMIF(data!$E:$E,科目余额表!$B11,data!H:H),0) -> 0 | M11: =IFERROR(SUMIF(data!$E:$E,科目余额表!$B11,data!I:I),0) -> 0 | N11: =IFERROR(SUMIF(data!$E:$E,科目余额表!$B11,data!J:J),0) -> 0 | O11: =IFERROR(SUMIF(data!$E:$E,科目余额表!$B11,data!K:K),0) -> 0 | P11: =IFERROR(SUMIF(data!$E:$E,科目余额表!$B11,data!L:L),0) -> 0 | Q11: =IFERROR(SUMIF(data!$E:$E,科目余额表!$B11,data!M:M),0) -> 0 | R11: =IFERROR(SUMIF(data!$E:$E,科目余额表!$B11,data!N:N),0) -> 0 | S11: =IFERROR(SUMIF(data!$E:$E,科目余额表!$B11,data!O:O),0) -> 0 | T11: =IFERROR(SUMIF(data!$E:$E,科目余额表!$B11,data!P:P),0) -> 0 | U11: =IFERROR(SUMIF(data!$E:$E,科目余额表!$B11,data!Q:Q),0) -> 0 | V11: =IFERROR(SUMIF(data!$E:$E,科目余额表!$B11,data!R:R),0) -> 0 | W11: =IFERROR(SUMIF(data!$E:$E,科目余额表!$B11,data!S:S),0) -> 0
B12: 10006 | C12: 现金-备用3 | D12: 0 | E12: 0 | F12: =D12+E12 -> 0 | G12: 现金 | H12: B | J12: 其中：现金 | L12: =IFERROR(SUMIF(data!$E:$E,科目余额表!$B12,data!H:H),0) -> 0 | M12: =IFERROR(SUMIF(data!$E:$E,科目余额表!$B12,data!I:I),0) -> 0 | N12: =IFERROR(SUMIF(data!$E:$E,科目余额表!$B12,data!J:J),0) -> 0 | O12: =IFERROR(SUMIF(data!$E:$E,科目余额表!$B12,data!K:K),0) -> 0 | P12: =IFERROR(SUMIF(data!$E:$E,科目余额表!$B12,data!L:L),0) -> 0 | Q12: =IFERROR(SUMIF(data!$E:$E,科目余额表!$B12,data!M:M),0) -> 0 | R12: =IFERROR(SUMIF(data!$E:$E,科目余额表!$B12,data!N:N),0) -> 0 | S12: =IFERROR(SUMIF(data!$E:$E,科目余额表!$B12,data!O:O),0) -> 0 | T12: =IFERROR(SUMIF(data!$E:$E,科目余额表!$B12,data!P:P),0) -> 0 | U12: =IFERROR(SUMIF(data!$E:$E,科目余额表!$B12,data!Q:Q),0) -> 0 | V12: =IFERROR(SUMIF(data!$E:$E,科目余额表!$B12,data!R:R),0) -> 0 | W12: =IFERROR(SUMIF(data!$E:$E,科目余额表!$B12,data!S:S),0) -> 0
B13: 10007 | C13: 现金-备用4 | D13: 0 | E13: 0 | F13: =D13+E13 -> 0 | G13: 现金 | H13: B | J13: 其中：现金 | L13: =IFERROR(SUMIF(data!$E:$E,科目余额表!$B13,data!H:H),0) -> 0 | M13: =IFERROR(SUMIF(data!$E:$E,科目余额表!$B13,data!I:I),0) -> 0 | N13: =IFERROR(SUMIF(data!$E:$E,科目余额表!$B13,data!J:J),0) -> 0 | O13: =IFERROR(SUMIF(data!$E:$E,科目余额表!$B13,data!K:K),0) -> 0 | P13: =IFERROR(SUMIF(data!$E:$E,科目余额表!$B13,data!L:L),0) -> 0 | Q13: =IFERROR(SUMIF(data!$E:$E,科目余额表!$B13,data!M:M),0) -> 0 | R13: =IFERROR(SUMIF(data!$E:$E,科目余额表!$B13,data!N:N),0) -> 0 | S13: =IFERROR(SUMIF(data!$E:$E,科目余额表!$B13,data!O:O),0) -> 0 | T13: =IFERROR(SUMIF(data!$E:$E,科目余额表!$B13,data!P:P),0) -> 0 | U13: =IFERROR(SUMIF(data!$E:$E,科目余额表!$B13,data!Q:Q),0) -> 0 | V13: =IFERROR(SUMIF(data!$E:$E,科目余额表!$B13,data!R:R),0) -> 0 | W13: =IFERROR(SUMIF(data!$E:$E,科目余额表!$B13,data!S:S),0) -> 0
B14: 10008 | C14: 现金-备用5 | D14: 0 | E14: 0 | F14: =D14+E14 -> 0 | G14: 现金 | H14: B | J14: 其中：现金 | L14: =IFERROR(SUMIF(data!$E:$E,科目余额表!$B14,data!H:H),0) -> 0 | M14: =IFERROR(SUMIF(data!$E:$E,科目余额表!$B14,data!I:I),0) -> 0 | N14: =IFERROR(SUMIF(data!$E:$E,科目余额表!$B14,data!J:J),0) -> 0 | O14: =IFERROR(SUMIF(data!$E:$E,科目余额表!$B14,data!K:K),0) -> 0 | P14: =IFERROR(SUMIF(data!$E:$E,科目余额表!$B14,data!L:L),0) -> 0 | Q14: =IFERROR(SUMIF(data!$E:$E,科目余额表!$B14,data!M:M),0) -> 0 | R14: =IFERROR(SUMIF(data!$E:$E,科目余额表!$B14,data!N:N),0) -> 0 | S14: =IFERROR(SUMIF(data!$E:$E,科目余额表!$B14,data!O:O),0) -> 0 | T14: =IFERROR(SUMIF(data!$E:$E,科目余额表!$B14,data!P:P),0) -> 0 | U14: =IFERROR(SUMIF(data!$E:$E,科目余额表!$B14,data!Q:Q),0) -> 0 | V14: =IFERROR(SUMIF(data!$E:$E,科目余额表!$B14,data!R:R),0) -> 0 | W14: =IFERROR(SUMIF(data!$E:$E,科目余额表!$B14,data!S:S),0) -> 0
B15: 10200 | C15: 银行存款-工行 | D15: 0 | E15: 0 | F15: =D15+E15 -> 0 | G15: 现金 | H15: B | J15: 银行存款 | L15: =IFERROR(SUMIF(data!$E:$E,科目余额表!$B15,data!H:H),0) -> 0 | M15: =IFERROR(SUMIF(data!$E:$E,科目余额表!$B15,data!I:I),0) -> 0 | N15: =IFERROR(SUMIF(data!$E:$E,科目余额表!$B15,data!J:J),0) -> 0 | O15: =IFERROR(SUMIF(data!$E:$E,科目余额表!$B15,data!K:K),0) -> 0 | P15: =IFERROR(SUMIF(data!$E:$E,科目余额表!$B15,data!L:L),0) -> 0 | Q15: =IFERROR(SUMIF(data!$E:$E,科目余额表!$B15,data!M:M),0) -> 0 | R15: =IFERROR(SUMIF(data!$E:$E,科目余额表!$B15,data!N:N),0) -> 0 | S15: =IFERROR(SUMIF(data!$E:$E,科目余额表!$B15,data!O:O),0) -> 0 | T15: =IFERROR(SUMIF(data!$E:$E,科目余额表!$B15,data!P:P),0) -> 0 | U15: =IFERROR(SUMIF(data!$E:$E,科目余额表!$B15,data!Q:Q),0) -> 0 | V15: =IFERROR(SUMIF(data!$E:$E,科目余额表!$B15,data!R:R),0) -> 0 | W15: =IFERROR(SUMIF(data!$E:$E,科目余额表!$B15,data!S:S),0) -> 0
B16: 10201 | C16: 银行存款-建行 | D16: 0 | E16: 0 | F16: =D16+E16 -> 0 | G16: 现金 | H16: B | J16: 银行存款 | L16: =IFERROR(SUMIF(data!$E:$E,科目余额表!$B16,data!H:H),0) -> 0 | M16: =IFERROR(SUMIF(data!$E:$E,科目余额表!$B16,data!I:I),0) -> 0 | N16: =IFERROR(SUMIF(data!$E:$E,科目余额表!$B16,data!J:J),0) -> 0 | O16: =IFERROR(SUMIF(data!$E:$E,科目余额表!$B16,data!K:K),0) -> 0 | P16: =IFERROR(SUMIF(data!$E:$E,科目余额表!$B16,data!L:L),0) -> 0 | Q16: =IFERROR(SUMIF(data!$E:$E,科目余额表!$B16,data!M:M),0) -> 0 | R16: =IFERROR(SUMIF(data!$E:$E,科目余额表!$B16,data!N:N),0) -> 0 | S16: =IFERROR(SUMIF(data!$E:$E,科目余额表!$B16,data!O:O),0) -> 0 | T16: =IFERROR(SUMIF(data!$E:$E,科目余额表!$B16,data!P:P),0) -> 0 | U16: =IFERROR(SUMIF(data!$E:$E,科目余额表!$B16,data!Q:Q),0) -> 0 | V16: =IFERROR(SUMIF(data!$E:$E,科目余额表!$B16,data!R:R),0) -> 0 | W16: =IFERROR(SUMIF(data!$E:$E,科目余额表!$B16,data!S:S),0) -> 0
B17: 10202 | C17: 银行存款-中行 | D17: 502911.93 | E17: -373696.36 | F17: =D17+E17 -> 129215.57 | G17: 现金 | H17: B | J17: 银行存款 | L17: =IFERROR(SUMIF(data!$E:$E,科目余额表!$B17,data!H:H),0) -> 266055.71 | M17: =IFERROR(SUMIF(data!$E:$E,科目余额表!$B17,data!I:I),0) -> 1861432.1 | N17: =IFERROR(SUMIF(data!$E:$E,科目余额表!$B17,data!J:J),0) -> 416772.27 | O17: =IFERROR(SUMIF(data!$E:$E,科目余额表!$B17,data!K:K),0) -> 1983004.8 | P17: =IFERROR(SUMIF(data!$E:$E,科目余额表!$B17,data!L:L),0) -> 1971149.9 | Q17: =IFERROR(SUMIF(data!$E:$E,科目余额表!$B17,data!M:M),0) -> 326646.65 | R17: =IFERROR(SUMIF(data!$E:$E,科目余额表!$B17,data!N:N),0) -> 695858.93 | S17: =IFERROR(SUMIF(data!$E:$E,科目余额表!$B17,data!O:O),0) -> 743383.3 | T17: =IFERROR(SUMIF(data!$E:$E,科目余额表!$B17,data!P:P),0) -> 181528.37 | U17: =IFERROR(SUMIF(data!$E:$E,科目余额表!$B17,data!Q:Q),0) -> 1038594.7 | V17: =IFERROR(SUMIF(data!$E:$E,科目余额表!$B17,data!R:R),0) -> 502911.93 | W17: =IFERROR(SUMIF(data!$E:$E,科目余额表!$B17,data!S:S),0) -> 129215.57
... B59: 12900 | C59: 客户模具 | D59: 0 | E59: 1675000 | F59: =D59+E59 -> 1675000 | G59: 客户模具 | H59: B | J59: 其他应收款 | L59: =IFERROR(SUMIF(data!$E:$E,科目余额表!$B59,data!H:H),0) -> 0 | M59: =IFERROR(SUMIF(data!$E:$E,科目余额表!$B59,data!I:I),0) -> 0 | N59: =IFERROR(SUMIF(data!$E:$E,科目余额表!$B59,data!J:J),0) -> 0 | O59: =IFERROR(SUMIF(data!$E:$E,科目余额表!$B59,data!K:K),0) -> 0 | P59: =IFERROR(SUMIF(data!$E:$E,科目余额表!$B59,data!L:L),0) -> -30000 | Q59: =IFERROR(SUMIF(data!$E:$E,科目余额表!$B59,data!M:M),0) -> 0 | R59: =IFERROR(SUMIF(data!$E:$E,科目余额表!$B59,data!N:N),0) -> 0 | S59: =IFERROR(SUMIF(data!$E:$E,科目余额表!$B59,data!O:O),0) -> 0 | T59: =IFERROR(SUMIF(data!$E:$E,科目余额表!$B59,data!P:P),0) -> 0 | U59: =IFERROR(SUMIF(data!$E:$E,科目余额表!$B59,data!Q:Q),0) -> 0 | V59: =IFERROR(SUMIF(data!$E:$E,科目余额表!$B59,data!R:R),0) -> 0 | W59: =IFERROR(SUMIF(data!$E:$E,科目余额表!$B59,data!S:S),0) -> 1675000
B60: 12901 | C60: 客户模具-跌价准备 | D60: 0 | E60: 0 | F60: =D60+E60 -> 0 | G60: 客户模具 | H60: B | J60: 0 | L60: =IFERROR(SUMIF(data!$E:$E,科目余额表!$B60,data!H:H),0) -> 0 | M60: =IFERROR(SUMIF(data!$E:$E,科目余额表!$B60,data!I:I),0) -> 0 | N60: =IFERROR(SUMIF(data!$E:$E,科目余额表!$B60,data!J:J),0) -> 0 | O60: =IFERROR(SUMIF(data!$E:$E,科目余额表!$B60,data!K:K),0) -> 0 | P60: =IFERROR(SUMIF(data!$E:$E,科目余额表!$B60,data!L:L),0) -> 0 | Q60: =IFERROR(SUMIF(data!$E:$E,科目余额表!$B60,data!M:M),0) -> 0 | R60: =IFERROR(SUMIF(data!$E:$E,科目余额表!$B60,data!N:N),0) -> 0 | S60: =IFERROR(SUMIF(data!$E:$E,科目余额表!$B60,data!O:O),0) -> 0 | T60: =IFERROR(SUMIF(data!$E:$E,科目余额表!$B60,data!P:P),0) -> 0 | U60: =IFERROR(SUMIF(data!$E:$E,科目余额表!$B60,data!Q:Q),0) -> 0 | V60: =IFERROR(SUMIF(data!$E:$E,科目余额表!$B60,data!R:R),0) -> 0 | W60: =IFERROR(SUMIF(data!$E:$E,科目余额表!$B60,data!S:S),0) -> 0
B61: 13001 | C61: 内部往来-本部 | D61: 0 | E61: 0 | F61: =D61+E61 -> 0 | G61: 内部往来 | H61: B | J61: 0 | L61: =IFERROR(SUMIF(data!$E:$E,科目余额表!$B61,data!H:H),0) -> 0 | M61: =IFERROR(SUMIF(data!$E:$E,科目余额表!$B61,data!I:I),0) -> 0 | N61: =IFERROR(SUMIF(data!$E:$E,科目余额表!$B61,data!J:J),0) -> 0 | O61: =IFERROR(SUMIF(data!$E:$E,科目余额表!$B61,data!K:K),0) -> 0 | P61: =IFERROR(SUMIF(data!$E:$E,科目余额表!$B61,data!L:L),0) -> 0 | Q61: =IFERROR(SUMIF(data!$E:$E,科目余额表!$B61,data!M:M),0) -> 0 | R61: =IFERROR(SUMIF(data!$E:$E,科目余额表!$B61,data!N:N),0) -> 0 | S61: =IFERROR(SUMIF(data!$E:$E,科目余额表!$B61,data!O:O),0) -> 0 | T61: =IFERROR(SUMIF(data!$E:$E,科目余额表!$B61,data!P:P),0) -> 0 | U61: =IFERROR(SUMIF(data!$E:$E,科目余额表!$B61,data!Q:Q),0) -> 0 | V61: =IFERROR(SUMIF(data!$E:$E,科目余额表!$B61,data!R:R),0) -> 0 | W61: =IFERROR(SUMIF(data!$E:$E,科目余额表!$B61,data!S:S),0) -> 0
B62: 13002 | C62: 内部往来-富晟物流 | D62: 0 | E62: 0 | F62: =D62+E62 -> 0 | G62: 内部往来 | H62: B | J62: 0 | L62: =IFERROR(SUMIF(data!$E:$E,科目余额表!$B62,data!H:H),0) -> 0 | M62: =IFERROR(SUMIF(data!$E:$E,科目余额表!$B62,data!I:I),0) -> 0 | N62: =IFERROR(SUMIF(data!$E:$E,科目余额表!$B62,data!J:J),0) -> 0 | O62: =IFERROR(SUMIF(data!$E:$E,科目余额表!$B62,data!K:K),0) -> 0 | P62: =IFERROR(SUMIF(data!$E:$E,科目余额表!$B62,data!L:L),0) -> 0 | Q62: =IFERROR(SUMIF(data!$E:$E,科目余额表!$B62,data!M:M),0) -> 0 | R62: =IFERROR(SUMIF(data!$E:$E,科目余额表!$B62,data!N:N),0) -> 0 | S62: =IFERROR(SUMIF(data!$E:$E,科目余额表!$B62,data!O:O),0) -> 0 | T62: =IFERROR(SUMIF(data!$E:$E,科目余额表!$B62,data!P:P),0) -> 0 | U62: =IFERROR(SUMIF(data!$E:$E,科目余额表!$B62,data!Q:Q),0) -> 0 | V62: =IFERROR(SUMIF(data!$E:$E,科目余额表!$B62,data!R:R),0) -> 0 | W62: =IFERROR(SUMIF(data!$E:$E,科目余额表!$B62,data!S:S),0) -> 0
B63: 13005 | C63: 内部往来-成都部件 | D63: 0 | E63: 0 | F63: =D63+E63 -> 0 | G63: 内部往来 | H63: B | J63: 0 | L63: =IFERROR(SUMIF(data!$E:$E,科目余额表!$B63,data!H:H),0) -> 0 | M63: =IFERROR(SUMIF(data!$E:$E,科目余额表!$B63,data!I:I),0) -> 0 | N63: =IFERROR(SUMIF(data!$E:$E,科目余额表!$B63,data!J:J),0) -> 0 | O63: =IFERROR(SUMIF(data!$E:$E,科目余额表!$B63,data!K:K),0) -> 0 | P63: =IFERROR(SUMIF(data!$E:$E,科目余额表!$B63,data!L:L),0) -> 0 | Q63: =IFERROR(SUMIF(data!$E:$E,科目余额表!$B63,data!M:M),0) -> 0 | R63: =IFERROR(SUMIF(data!$E:$E,科目余额表!$B63,data!N:N),0) -> 0 | S63: =IFERROR(SUMIF(data!$E:$E,科目余额表!$B63,data!O:O),0) -> 0 | T63: =IFERROR(SUMIF(data!$E:$E,科目余额表!$B63,data!P:P),0) -> 0 | U63: =IFERROR(SUMIF(data!$E:$E,科目余额表!$B63,data!Q:Q),0) -> 0 | V63: =IFERROR(SUMIF(data!$E:$E,科目余额表!$B63,data!R:R),0) -> 0 | W63: =IFERROR(SUMIF(data!$E:$E,科目余额表!$B63,data!S:S),0) -> 0
B64: 13006 | C64: 内部往来-长春久泰 | D64: 0 | E64: 0 | F64: =D64+E64 -> 0 | G64: 内部往来 | H64: B | J64: 0 | L64: =IFERROR(SUMIF(data!$E:$E,科目余额表!$B64,data!H:H),0) -> 0 | M64: =IFERROR(SUMIF(data!$E:$E,科目余额表!$B64,data!I:I),0) -> 0 | N64: =IFERROR(SUMIF(data!$E:$E,科目余额表!$B64,data!J:J),0) -> 0 | O64: =IFERROR(SUMIF(data!$E:$E,科目余额表!$B64,data!K:K),0) -> 0 | P64: =IFERROR(SUMIF(data!$E:$E,科目余额表!$B64,data!L:L),0) -> 0 | Q64: =IFERROR(SUMIF(data!$E:$E,科目余额表!$B64,data!M:M),0) -> 0 | R64: =IFERROR(SUMIF(data!$E:$E,科目余额表!$B64,data!N:N),0) -> 0 | S64: =IFERROR(SUMIF(data!$E:$E,科目余额表!$B64,data!O:O),0) -> 0 | T64: =IFERROR(SUMIF(data!$E:$E,科目余额表!$B64,data!P:P),0) -> 0 | U64: =IFERROR(SUMIF(data!$E:$E,科目余额表!$B64,data!Q:Q),0) -> 0 | V64: =IFERROR(SUMIF(data!$E:$E,科目余额表!$B64,data!R:R),0) -> 0 | W64: =IFERROR(SUMIF(data!$E:$E,科目余额表!$B64,data!S:S),0) -> 0
B65: 13007 | C65: 内部往来-车桥 | D65: 0 | E65: 0 | F65: =D65+E65 -> 0 | G65: 内部往来 | H65: B | J65: 0 | L65: =IFERROR(SUMIF(data!$E:$E,科目余额表!$B65,data!H:H),0) -> 0 | M65: =IFERROR(SUMIF(data!$E:$E,科目余额表!$B65,data!I:I),0) -> 0 | N65: =IFERROR(SUMIF(data!$E:$E,科目余额表!$B65,data!J:J),0) -> 0 | O65: =IFERROR(SUMIF(data!$E:$E,科目余额表!$B65,data!K:K),0) -> 0 | P65: =IFERROR(SUMIF(data!$E:$E,科目余额表!$B65,data!L:L),0) -> 0 | Q65: =IFERROR(SUMIF(data!$E:$E,科目余额表!$B65,data!M:M),0) -> 0 | R65: =IFERROR(SUMIF(data!$E:$E,科目余额表!$B65,data!N:N),0) -> 0 | S65: =IFERROR(SUMIF(data!$E:$E,科目余额表!$B65,data!O:O),0) -> 0 | T65: =IFERROR(SUMIF(data!$E:$E,科目余额表!$B65,data!P:P),0) -> 0 | U65: =IFERROR(SUMIF(data!$E:$E,科目余额表!$B65,data!Q:Q),0) -> 0 | V65: =IFERROR(SUMIF(data!$E:$E,科目余额表!$B65,data!R:R),0) -> 0 | W65: =IFERROR(SUMIF(data!$E:$E,科目余额表!$B65,data!S:S),0) -> 0
B66: 13008 | C66: 内部往来-长春饰件 | D66: 0 | E66: 0 | F66: =D66+E66 -> 0 | G66: 内部往来 | H66: B | J66: 0 | L66: =IFERROR(SUMIF(data!$E:$E,科目余额表!$B66,data!H:H),0) -> 0 | M66: =IFERROR(SUMIF(data!$E:$E,科目余额表!$B66,data!I:I),0) -> 0 | N66: =IFERROR(SUMIF(data!$E:$E,科目余额表!$B66,data!J:J),0) -> 0 | O66: =IFERROR(SUMIF(data!$E:$E,科目余额表!$B66,data!K:K),0) -> 0 | P66: =IFERROR(SUMIF(data!$E:$E,科目余额表!$B66,data!L:L),0) -> 0 | Q66: =IFERROR(SUMIF(data!$E:$E,科目余额表!$B66,data!M:M),0) -> 0 | R66: =IFERROR(SUMIF(data!$E:$E,科目余额表!$B66,data!N:N),0) -> 0 | S66: =IFERROR(SUMIF(data!$E:$E,科目余额表!$B66,data!O:O),0) -> 0 | T66: =IFERROR(SUMIF(data!$E:$E,科目余额表!$B66,data!P:P),0) -> 0 | U66: =IFERROR(SUMIF(data!$E:$E,科目余额表!$B66,data!Q:Q),0) -> 0 | V66: =IFERROR(SUMIF(data!$E:$E,科目余额表!$B66,data!R:R),0) -> 0 | W66: =IFERROR(SUMIF(data!$E:$E,科目余额表!$B66,data!S:S),0) -> 0
B67: 13011 | C67: 内部往来-长春李尔座椅 | D67: 0 | E67: 0 | F67: =D67+E67 -> 0 | G67: 内部往来 | H67: B | J67: 0 | L67: =IFERROR(SUMIF(data!$E:$E,科目余额表!$B67,data!H:H),0) -> 0 | M67: =IFERROR(SUMIF(data!$E:$E,科目余额表!$B67,data!I:I),0) -> 0 | N67: =IFERROR(SUMIF(data!$E:$E,科目余额表!$B67,data!J:J),0) -> 0 | O67: =IFERROR(SUMIF(data!$E:$E,科目余额表!$B67,data!K:K),0) -> 0 | P67: =IFERROR(SUMIF(data!$E:$E,科目余额表!$B67,data!L:L),0) -> 0 | Q67: =IFERROR(SUMIF(data!$E:$E,科目余额表!$B67,data!M:M),0) -> 0 | R67: =IFERROR(SUMIF(data!$E:$E,科目余额表!$B67,data!N:N),0) -> 0 | S67: =IFERROR(SUMIF(data!$E:$E,科目余额表!$B67,data!O:O),0) -> 0 | T67: =IFERROR(SUMIF(data!$E:$E,科目余额表!$B67,data!P:P),0) -> 0 | U67: =IFERROR(SUMIF(data!$E:$E,科目余额表!$B67,data!Q:Q),0) -> 0 | V67: =IFERROR(SUMIF(data!$E:$E,科目余额表!$B67,data!R:R),0) -> 0 | W67: =IFERROR(SUMIF(data!$E:$E,科目余额表!$B67,data!S:S),0) -> 0
B68: 13013 | C68: 内部往来-佛山李尔座椅 | D68: 0 | E68: 0 | F68: =D68+E68 -> 0 | G68: 内部往来 | H68: B | J68: 0 | L68: =IFERROR(SUMIF(data!$E:$E,科目余额表!$B68,data!H:H),0) -> 0 | M68: =IFERROR(SUMIF(data!$E:$E,科目余额表!$B68,data!I:I),0) -> 0 | N68: =IFERROR(SUMIF(data!$E:$E,科目余额表!$B68,data!J:J),0) -> 0 | O68: =IFERROR(SUMIF(data!$E:$E,科目余额表!$B68,data!K:K),0) -> 0 | P68: =IFERROR(SUMIF(data!$E:$E,科目余额表!$B68,data!L:L),0) -> 0 | Q68: =IFERROR(SUMIF(data!$E:$E,科目余额表!$B68,data!M:M),0) -> 0 | R68: =IFERROR(SUMIF(data!$E:$E,科目余额表!$B68,data!N:N),0) -> 0 | S68: =IFERROR(SUMIF(data!$E:$E,科目余额表!$B68,data!O:O),0) -> 0 | T68: =IFERROR(SUMIF(data!$E:$E,科目余额表!$B68,data!P:P),0) -> 0 | U68: =IFERROR(SUMIF(data!$E:$E,科目余额表!$B68,data!Q:Q),0) -> 0 | V68: =IFERROR(SUMIF(data!$E:$E,科目余额表!$B68,data!R:R),0) -> 0 | W68: =IFERROR(SUMIF(data!$E:$E,科目余额表!$B68,data!S:S),0) -> 0
B69: 13014 | C69: 内部往来-成都饰件 | D69: 0 | E69: 0 | F69: =D69+E69 -> 0 | G69: 内部往来 | H69: B | J69: 0 | L69: =IFERROR(SUMIF(data!$E:$E,科目余额表!$B69,data!H:H),0) -> 0 | M69: =IFERROR(SUMIF(data!$E:$E,科目余额表!$B69,data!I:I),0) -> 0 | N69: =IFERROR(SUMIF(data!$E:$E,科目余额表!$B69,data!J:J),0) -> 0 | O69: =IFERROR(SUMIF(data!$E:$E,科目余额表!$B69,data!K:K),0) -> 0 | P69: =IFERROR(SUMIF(data!$E:$E,科目余额表!$B69,data!L:L),0) -> 0 | Q69: =IFERROR(SUMIF(data!$E:$E,科目余额表!$B69,data!M:M),0) -> 0 | R69: =IFERROR(SUMIF(data!$E:$E,科目余额表!$B69,data!N:N),0) -> 0 | S69: =IFERROR(SUMIF(data!$E:$E,科目余额表!$B69,data!O:O),0) -> 0 | T69: =IFERROR(SUMIF(data!$E:$E,科目余额表!$B69,data!P:P),0) -> 0 | U69: =IFERROR(SUMIF(data!$E:$E,科目余额表!$B69,data!Q:Q),0) -> 0 | V69: =IFERROR(SUMIF(data!$E:$E,科目余额表!$B69,data!R:R),0) -> 0 | W69: =IFERROR(SUMIF(data!$E:$E,科目余额表!$B69,data!S:S),0) -> 0
B70: 13015 | C70: 内部往来-佛山饰件 | D70: 0 | E70: 0 | F70: =D70+E70 -> 0 | G70: 内部往来 | H70: B | J70: 0 | L70: =IFERROR(SUMIF(data!$E:$E,科目余额表!$B70,data!H:H),0) -> 0 | M70: =IFERROR(SUMIF(data!$E:$E,科目余额表!$B70,data!I:I),0) -> 0 | N70: =IFERROR(SUMIF(data!$E:$E,科目余额表!$B70,data!J:J),0) -> 0 | O70: =IFERROR(SUMIF(data!$E:$E,科目余额表!$B70,data!K:K),0) -> 0 | P70: =IFERROR(SUMIF(data!$E:$E,科目余额表!$B70,data!L:L),0) -> 0 | Q70: =IFERROR(SUMIF(data!$E:$E,科目余额表!$B70,data!M:M),0) -> 0 | R70: =IFERROR(SUMIF(data!$E:$E,科目余额表!$B70,data!N:N),0) -> 0 | S70: =IFERROR(SUMIF(data!$E:$E,科目余额表!$B70,data!O:O),0) -> 0 | T70: =IFERROR(SUMIF(data!$E:$E,科目余额表!$B70,data!P:P),0) -> 0 | U70: =IFERROR(SUMIF(data!$E:$E,科目余额表!$B70,data!Q:Q),0) -> 0 | V70: =IFERROR(SUMIF(data!$E:$E,科目余额表!$B70,data!R:R),0) -> 0 | W70: =IFERROR(SUMIF(data!$E:$E,科目余额表!$B70,data!S:S),0) -> 0
B71: 13016 | C71: 内部往来-成都久泰 | D71: 0 | E71: 0 | F71: =D71+E71 -> 0 | G71: 内部往来 | H71: B | J71: 0 | L71: =IFERROR(SUMIF(data!$E:$E,科目余额表!$B71,data!H:H),0) -> 0 | M71: =IFERROR(SUMIF(data!$E:$E,科目余额表!$B71,data!I:I),0) -> 0 | N71: =IFERROR(SUMIF(data!$E:$E,科目余额表!$B71,data!J:J),0) -> 0 | O71: =IFERROR(SUMIF(data!$E:$E,科目余额表!$B71,data!K:K),0) -> 0 | P71: =IFERROR(SUMIF(data!$E:$E,科目余额表!$B71,data!L:L),0) -> 0 | Q71: =IFERROR(SUMIF(data!$E:$E,科目余额表!$B71,data!M:M),0) -> 0 | R71: =IFERROR(SUMIF(data!$E:$E,科目余额表!$B71,data!N:N),0) -> 0 | S71: =IFERROR(SUMIF(data!$E:$E,科目余额表!$B71,data!O:O),0) -> 0 | T71: =IFERROR(SUMIF(data!$E:$E,科目余额表!$B71,data!P:P),0) -> 0 | U71: =IFERROR(SUMIF(data!$E:$E,科目余额表!$B71,data!Q:Q),0) -> 0 | V71: =IFERROR(SUMIF(data!$E:$E,科目余额表!$B71,data!R:R),0) -> 0 | W71: =IFERROR(SUMIF(data!$E:$E,科目余额表!$B71,data!S:S),0) -> 0
... B161: 13120 | C161: 内部往来-备用45 | D161: 0 | E161: 0 | F161: =D161+E161 -> 0 | G161: 内部往来 | H161: B | J161: 0 | L161: =IFERROR(SUMIF(data!$E:$E,科目余额表!$B161,data!H:H),0) -> 0 | M161: =IFERROR(SUMIF(data!$E:$E,科目余额表!$B161,data!I:I),0) -> 0 | N161: =IFERROR(SUMIF(data!$E:$E,科目余额表!$B161,data!J:J),0) -> 0 | O161: =IFERROR(SUMIF(data!$E:$E,科目余额表!$B161,data!K:K),0) -> 0 | P161: =IFERROR(SUMIF(data!$E:$E,科目余额表!$B161,data!L:L),0) -> 0 | Q161: =IFERROR(SUMIF(data!$E:$E,科目余额表!$B161,data!M:M),0) -> 0 | R161: =IFERROR(SUMIF(data!$E:$E,科目余额表!$B161,data!N:N),0) -> 0 | S161: =IFERROR(SUMIF(data!$E:$E,科目余额表!$B161,data!O:O),0) -> 0 | T161: =IFERROR(SUMIF(data!$E:$E,科目余额表!$B161,data!P:P),0) -> 0 | U161: =IFERROR(SUMIF(data!$E:$E,科目余额表!$B161,data!Q:Q),0) -> 0 | V161: =IFERROR(SUMIF(data!$E:$E,科目余额表!$B161,data!R:R),0) -> 0 | W161: =IFERROR(SUMIF(data!$E:$E,科目余额表!$B161,data!S:S),0) -> 0
B162: 14000 | C162: 存货-在途材料 | D162: 0 | E162: 0 | F162: =D162+E162 -> 0 | G162: 存货 | H162: B | J162: 在途材料 | L162: =IFERROR(SUMIF(data!$E:$E,科目余额表!$B162,data!H:H),0) -> 0 | M162: =IFERROR(SUMIF(data!$E:$E,科目余额表!$B162,data!I:I),0) -> 0 | N162: =IFERROR(SUMIF(data!$E:$E,科目余额表!$B162,data!J:J),0) -> 0 | O162: =IFERROR(SUMIF(data!$E:$E,科目余额表!$B162,data!K:K),0) -> 0 | P162: =IFERROR(SUMIF(data!$E:$E,科目余额表!$B162,data!L:L),0) -> 0 | Q162: =IFERROR(SUMIF(data!$E:$E,科目余额表!$B162,data!M:M),0) -> 0 | R162: =IFERROR(SUMIF(data!$E:$E,科目余额表!$B162,data!N:N),0) -> 0 | S162: =IFERROR(SUMIF(data!$E:$E,科目余额表!$B162,data!O:O),0) -> 0 | T162: =IFERROR(SUMIF(data!$E:$E,科目余额表!$B162,data!P:P),0) -> 0 | U162: =IFERROR(SUMIF(data!$E:$E,科目余额表!$B162,data!Q:Q),0) -> 0 | V162: =IFERROR(SUMIF(data!$E:$E,科目余额表!$B162,data!R:R),0) -> 0 | W162: =IFERROR(SUMIF(data!$E:$E,科目余额表!$B162,data!S:S),0) -> 0
B163: 14100 | C163: 存货-原材料 | D163: 0 | E163: 0 | F163: =D163+E163 -> 0 | G163: 存货 | H163: B | J163: 其中：原材料 | L163: =IFERROR(SUMIF(data!$E:$E,科目余额表!$B163,data!H:H),0) -> 0 | M163: =IFERROR(SUMIF(data!$E:$E,科目余额表!$B163,data!I:I),0) -> 0 | N163: =IFERROR(SUMIF(data!$E:$E,科目余额表!$B163,data!J:J),0) -> 0 | O163: =IFERROR(SUMIF(data!$E:$E,科目余额表!$B163,data!K:K),0) -> 0 | P163: =IFERROR(SUMIF(data!$E:$E,科目余额表!$B163,data!L:L),0) -> 0 | Q163: =IFERROR(SUMIF(data!$E:$E,科目余额表!$B163,data!M:M),0) -> 0 | R163: =IFERROR(SUMIF(data!$E:$E,科目余额表!$B163,data!N:N),0) -> 0 | S163: =IFERROR(SUMIF(data!$E:$E,科目余额表!$B163,data!O:O),0) -> 0 | T163: =IFERROR(SUMIF(data!$E:$E,科目余额表!$B163,data!P:P),0) -> 0 | U163: =IFERROR(SUMIF(data!$E:$E,科目余额表!$B163,data!Q:Q),0) -> 0 | V163: =IFERROR(SUMIF(data!$E:$E,科目余额表!$B163,data!R:R),0) -> 0 | W163: =IFERROR(SUMIF(data!$E:$E,科目余额表!$B163,data!S:S),0) -> 0
B164: 14101 | C164: 存货-外购件 | D164: 1927430.6 | E164: -96855.37 | F164: =D164+E164 -> 1830575.2 | G164: 存货 | H164: B | J164: 外购件 | L164: =IFERROR(SUMIF(data!$E:$E,科目余额表!$B164,data!H:H),0) -> 3386202.4 | M164: =IFERROR(SUMIF(data!$E:$E,科目余额表!$B164,data!I:I),0) -> 3154865.7 | N164: =IFERROR(SUMIF(data!$E:$E,科目余额表!$B164,data!J:J),0) -> 3236778.5 | O164: =IFERROR(SUMIF(data!$E:$E,科目余额表!$B164,data!K:K),0) -> 2737442.3 | P164: =IFERROR(SUMIF(data!$E:$E,科目余额表!$B164,data!L:L),0) -> 2662628.1 | Q164: =IFERROR(SUMIF(data!$E:$E,科目余额表!$B164,data!M:M),0) -> 2150055.4 | R164: =IFERROR(SUMIF(data!$E:$E,科目余额表!$B164,data!N:N),0) -> 1823879.7 | S164: =IFERROR(SUMIF(data!$E:$E,科目余额表!$B164,data!O:O),0) -> 1818564.8 | T164: =IFERROR(SUMIF(data!$E:$E,科目余额表!$B164,data!P:P),0) -> 1823726 | U164: =IFERROR(SUMIF(data!$E:$E,科目余额表!$B164,data!Q:Q),0) -> 1866382.5 | V164: =IFERROR(SUMIF(data!$E:$E,科目余额表!$B164,data!R:R),0) -> 1927430.6 | W164: =IFERROR(SUMIF(data!$E:$E,科目余额表!$B164,data!S:S),0) -> 1830575.2
B165: 14102 | C165: 存货-自制半成品 | D165: 0 | E165: 0 | F165: =D165+E165 -> 0 | G165: 存货 | H165: B | J165: 自制半成品 | L165: =IFERROR(SUMIF(data!$E:$E,科目余额表!$B165,data!H:H),0) -> 0 | M165: =IFERROR(SUMIF(data!$E:$E,科目余额表!$B165,data!I:I),0) -> 0 | N165: =IFERROR(SUMIF(data!$E:$E,科目余额表!$B165,data!J:J),0) -> 0 | O165: =IFERROR(SUMIF(data!$E:$E,科目余额表!$B165,data!K:K),0) -> 0 | P165: =IFERROR(SUMIF(data!$E:$E,科目余额表!$B165,data!L:L),0) -> 0 | Q165: =IFERROR(SUMIF(data!$E:$E,科目余额表!$B165,data!M:M),0) -> 0 | R165: =IFERROR(SUMIF(data!$E:$E,科目余额表!$B165,data!N:N),0) -> 0 | S165: =IFERROR(SUMIF(data!$E:$E,科目余额表!$B165,data!O:O),0) -> 0 | T165: =IFERROR(SUMIF(data!$E:$E,科目余额表!$B165,data!P:P),0) -> 0 | U165: =IFERROR(SUMIF(data!$E:$E,科目余额表!$B165,data!Q:Q),0) -> 0 | V165: =IFERROR(SUMIF(data!$E:$E,科目余额表!$B165,data!R:R),0) -> 0 | W165: =IFERROR(SUMIF(data!$E:$E,科目余额表!$B165,data!S:S),0) -> 0
B166: 14103 | C166: 存货-包装物 | D166: 0 | E166: 0 | F166: =D166+E166 -> 0 | G166: 存货 | H166: B | J166: 周转材料 | L166: =IFERROR(SUMIF(data!$E:$E,科目余额表!$B166,data!H:H),0) -> 0 | M166: =IFERROR(SUMIF(data!$E:$E,科目余额表!$B166,data!I:I),0) -> 0 | N166: =IFERROR(SUMIF(data!$E:$E,科目余额表!$B166,data!J:J),0) -> 0 | O166: =IFERROR(SUMIF(data!$E:$E,科目余额表!$B166,data!K:K),0) -> 0 | P166: =IFERROR(SUMIF(data!$E:$E,科目余额表!$B166,data!L:L),0) -> 0 | Q166: =IFERROR(SUMIF(data!$E:$E,科目余额表!$B166,data!M:M),0) -> 0 | R166: =IFERROR(SUMIF(data!$E:$E,科目余额表!$B166,data!N:N),0) -> 0 | S166: =IFERROR(SUMIF(data!$E:$E,科目余额表!$B166,data!O:O),0) -> 0 | T166: =IFERROR(SUMIF(data!$E:$E,科目余额表!$B166,data!P:P),0) -> 0 | U166: =IFERROR(SUMIF(data!$E:$E,科目余额表!$B166,data!Q:Q),0) -> 0 | V166: =IFERROR(SUMIF(data!$E:$E,科目余额表!$B166,data!R:R),0) -> 0 | W166: =IFERROR(SUMIF(data!$E:$E,科目余额表!$B166,data!S:S),0) -> 0
B167: 14104 | C167: 存货-辅助材料 | D167: 0 | E167: 0 | F167: =D167+E167 -> 0 | G167: 存货 | H167: B | J167: 周转材料 | L167: =IFERROR(SUMIF(data!$E:$E,科目余额表!$B167,data!H:H),0) -> 0 | M167: =IFERROR(SUMIF(data!$E:$E,科目余额表!$B167,data!I:I),0) -> 0 | N167: =IFERROR(SUMIF(data!$E:$E,科目余额表!$B167,data!J:J),0) -> 0 | O167: =IFERROR(SUMIF(data!$E:$E,科目余额表!$B167,data!K:K),0) -> 0 | P167: =IFERROR(SUMIF(data!$E:$E,科目余额表!$B167,data!L:L),0) -> 0 | Q167: =IFERROR(SUMIF(data!$E:$E,科目余额表!$B167,data!M:M),0) -> 0 | R167: =IFERROR(SUMIF(data!$E:$E,科目余额表!$B167,data!N:N),0) -> 0 | S167: =IFERROR(SUMIF(data!$E:$E,科目余额表!$B167,data!O:O),0) -> 0 | T167: =IFERROR(SUMIF(data!$E:$E,科目余额表!$B167,data!P:P),0) -> 0 | U167: =IFERROR(SUMIF(data!$E:$E,科目余额表!$B167,data!Q:Q),0) -> 0 | V167: =IFERROR(SUMIF(data!$E:$E,科目余额表!$B167,data!R:R),0) -> 0 | W167: =IFERROR(SUMIF(data!$E:$E,科目余额表!$B167,data!S:S),0) -> 0
B168: 14105 | C168: 存货-备件 | D168: 0 | E168: 0 | F168: =D168+E168 -> 0 | G168: 存货 | H168: B | J168: 备件 | L168: =IFERROR(SUMIF(data!$E:$E,科目余额表!$B168,data!H:H),0) -> 0 | M168: =IFERROR(SUMIF(data!$E:$E,科目余额表!$B168,data!I:I),0) -> 0 | N168: =IFERROR(SUMIF(data!$E:$E,科目余额表!$B168,data!J:J),0) -> 0 | O168: =IFERROR(SUMIF(data!$E:$E,科目余额表!$B168,data!K:K),0) -> 0 | P168: =IFERROR(SUMIF(data!$E:$E,科目余额表!$B168,data!L:L),0) -> 0 | Q168: =IFERROR(SUMIF(data!$E:$E,科目余额表!$B168,data!M:M),0) -> 0 | R168: =IFERROR(SUMIF(data!$E:$E,科目余额表!$B168,data!N:N),0) -> 0 | S168: =IFERROR(SUMIF(data!$E:$E,科目余额表!$B168,data!O:O),0) -> 0 | T168: =IFERROR(SUMIF(data!$E:$E,科目余额表!$B168,data!P:P),0) -> 0 | U168: =IFERROR(SUMIF(data!$E:$E,科目余额表!$B168,data!Q:Q),0) -> 0 | V168: =IFERROR(SUMIF(data!$E:$E,科目余额表!$B168,data!R:R),0) -> 0 | W168: =IFERROR(SUMIF(data!$E:$E,科目余额表!$B168,data!S:S),0) -> 0
B169: 14106 | C169: 存货-低值易耗品 | D169: 0 | E169: 0 | F169: =D169+E169 -> 0 | G169: 存货 | H169: B | J169: 周转材料 | L169: =IFERROR(SUMIF(data!$E:$E,科目余额表!$B169,data!H:H),0) -> 0 | M169: =IFERROR(SUMIF(data!$E:$E,科目余额表!$B169,data!I:I),0) -> 0 | N169: =IFERROR(SUMIF(data!$E:$E,科目余额表!$B169,data!J:J),0) -> 0 | O169: =IFERROR(SUMIF(data!$E:$E,科目余额表!$B169,data!K:K),0) -> 0 | P169: =IFERROR(SUMIF(data!$E:$E,科目余额表!$B169,data!L:L),0) -> 0 | Q169: =IFERROR(SUMIF(data!$E:$E,科目余额表!$B169,data!M:M),0) -> 0 | R169: =IFERROR(SUMIF(data!$E:$E,科目余额表!$B169,data!N:N),0) -> 0 | S169: =IFERROR(SUMIF(data!$E:$E,科目余额表!$B169,data!O:O),0) -> 0 | T169: =IFERROR(SUMIF(data!$E:$E,科目余额表!$B169,data!P:P),0) -> 0 | U169: =IFERROR(SUMIF(data!$E:$E,科目余额表!$B169,data!Q:Q),0) -> 0 | V169: =IFERROR(SUMIF(data!$E:$E,科目余额表!$B169,data!R:R),0) -> 0 | W169: =IFERROR(SUMIF(data!$E:$E,科目余额表!$B169,data!S:S),0) -> 0
B170: 14107 | C170: 存货-在制品 | D170: 144684.94 | E170: -93613.65 | F170: =D170+E170 -> 51071.29 | G170: 存货 | H170: B | J170: 在制品 | L170: =IFERROR(SUMIF(data!$E:$E,科目余额表!$B170,data!H:H),0) -> 216210.41 | M170: =IFERROR(SUMIF(data!$E:$E,科目余额表!$B170,data!I:I),0) -> 138070.02 | N170: =IFERROR(SUMIF(data!$E:$E,科目余额表!$B170,data!J:J),0) -> 149164.28 | O170: =IFERROR(SUMIF(data!$E:$E,科目余额表!$B170,data!K:K),0) -> 182727.77 | P170: =IFERROR(SUMIF(data!$E:$E,科目余额表!$B170,data!L:L),0) -> 187962.34 | Q170: =IFERROR(SUMIF(data!$E:$E,科目余额表!$B170,data!M:M),0) -> 92276.61 | R170: =IFERROR(SUMIF(data!$E:$E,科目余额表!$B170,data!N:N),0) -> 115953.53 | S170: =IFERROR(SUMIF(data!$E:$E,科目余额表!$B170,data!O:O),0) -> 100864.33 | T170: =IFERROR(SUMIF(data!$E:$E,科目余额表!$B170,data!P:P),0) -> 240232.79 | U170: =IFERROR(SUMIF(data!$E:$E,科目余额表!$B170,data!Q:Q),0) -> 84140.85 | V170: =IFERROR(SUMIF(data!$E:$E,科目余额表!$B170,data!R:R),0) -> 144684.94 | W170: =IFERROR(SUMIF(data!$E:$E,科目余额表!$B170,data!S:S),0) -> 51071.29
B171: 14200 | C171: 存货-产成品 | D171: 539750.12 | E171: 422519.63 | F171: =D171+E171 -> 962269.75 | G171: 存货 | H171: B | J171: 库存商品 | L171: =IFERROR(SUMIF(data!$E:$E,科目余额表!$B171,data!H:H),0) -> 1400443 | M171: =IFERROR(SUMIF(data!$E:$E,科目余额表!$B171,data!I:I),0) -> 884617.88 | N171: =IFERROR(SUMIF(data!$E:$E,科目余额表!$B171,data!J:J),0) -> 1031980.3 | O171: =IFERROR(SUMIF(data!$E:$E,科目余额表!$B171,data!K:K),0) -> 645984.59 | P171: =IFERROR(SUMIF(data!$E:$E,科目余额表!$B171,data!L:L),0) -> 686306.48 | Q171: =IFERROR(SUMIF(data!$E:$E,科目余额表!$B171,data!M:M),0) -> 647538.96 | R171: =IFERROR(SUMIF(data!$E:$E,科目余额表!$B171,data!N:N),0) -> 492946.33 | S171: =IFERROR(SUMIF(data!$E:$E,科目余额表!$B171,data!O:O),0) -> 437049.59 | T171: =IFERROR(SUMIF(data!$E:$E,科目余额表!$B171,data!P:P),0) -> 889325.35 | U171: =IFERROR(SUMIF(data!$E:$E,科目余额表!$B171,data!Q:Q),0) -> 552581.19 | V171: =IFERROR(SUMIF(data!$E:$E,科目余额表!$B171,data!R:R),0) -> 539750.12 | W171: =IFERROR(SUMIF(data!$E:$E,科目余额表!$B171,data!S:S),0) -> 962269.75
...

Sheet data
A1: Inalfa 报表代码 | B1: Inalfa 报表描述 | C1: Inalfa 科目代码 | D1: Inalfa 科目描述 | E1: 富晟 科目代码 | F1: 富晟 科目描述 | G1: 富晟报表 -汇总到 | H1: Jan | I1: Feb | J1: Mar | K1: Apr | L1: May | M1: Jun | N1: Jul | O1: Aug | P1: Sep | Q1: Oct | R1: Nov | S1: Dec | T1: Total
A2: 10300 | B2: Capitalized R&D-At cost | C2: 1100-1311 | D2: 长期待摊费用 | E2: 18001 | F2: 无形资产-专利 | G2: 无形资产 | H2: =25048208.71 -> 25048209 | I2: 25048209 | J2: 25048209 | K2: 25048209 | L2: 25048209 | M2: 25048209 | N2: 25048209 | O2: 25048209 | P2: 25048209 | Q2: 25048209 | R2: 28884204 | S2: =24359036.44 -> 24359036 | U2: 长期待摊
A3: 10300 | B3: Capitalized R&D-At cost | C3: 1100-1312 | D3: ProjectManagemtOutofRegion | E3: 18001 | F3: 无形资产-专利 | G3: 无形资产 | H3: 4521754.4 | I3: 4585446.6 | J3: 4635869.6 | K3: 4670369.5 | L3: 4701016 | M3: 4744796.8 | N3: 4790766.7 | O3: 4836736.5 | P3: 4895840.6 | Q3: 4928676.2 | R3: 4961511.8 | S3: 4979024.1
A4: 10300 | B4: Capitalized R&D-At cost | C4: 1100-1354 | D4: Outsourced testing costs | E4: 18001 | F4: 无形资产-专利 | G4: 无形资产 | H4: 113626.27 | I4: 113626.27 | J4: 113626.27 | K4: 113626.27 | L4: 113626.27 | M4: 113626.27 | N4: 113626.27 | O4: 113626.27 | P4: 113626.27 | Q4: 113626.27 | R4: 113626.27 | S4: 113626.27
A5: 10300 | B5: Capitalized R&D-At cost | C5: 1100-1356 | D5: Test electro equipment costs | E5: 18001 | F5: 无形资产-专利 | G5: 无形资产 | H5: 28514.52 | I5: 28514.52 | J5: 28514.52 | K5: 28514.52 | L5: 28514.52 | M5: 28514.52 | N5: 28514.52 | O5: 28514.52 | P5: 31522.27 | Q5: 31522.27 | R5: 31522.27 | S5: 31522.27
A6: 10300 | B6: Capitalized R&D-At cost | C6: 1100-1358 | D6: 长期待摊费用-原材料 | E6: 18001 | F6: 无形资产-专利 | G6: 无形资产 | H6: 3738059 | I6: 3765399.7 | J6: 3818185 | K6: 3856816.8 | L6: 3427735.2 | M6: 3247165.7 | N6: 3282789.8 | O6: 3756599.4 | P6: 3876557.3 | Q6: 3953031.1 | R6: 3972575.5 | S6: 3972575.5
A7: 10300 | B7: Capitalized R&D-At cost | C7: 1100-1360 | D7: 长期待摊费用-运费 | E7: 18001 | F7: 无形资产-专利 | G7: 无形资产 | H7: 523167.53 | I7: 530320.36 | J7: 542176.36 | K7: 564440.82 | L7: 567248.03 | M7: 568584.03 | N7: 568677.42 | O7: 556885.23 | P7: 569369.04 | Q7: 572089.54 | R7: 572339.54 | S7: 562517.23
A8: 10300 | B8: Capitalized R&D-At cost | C8: 1100-1362 | D8: 长期待摊费用-运营成本 | E8: 18001 | F8: 无形资产-专利 | G8: 无形资产 | H8: 937652.95 | I8: 946308.95 | J8: 958820.95 | K8: 977636.95 | L8: 990580.95 | M8: 1004212.3 | N8: 1017972.3 | O8: 1056227.9 | P8: 1086039.1 | Q8: 1088471.1 | R8: 1088471.1 | S8: 1088471.1
A9: 10300 | B9: Capitalized R&D-At cost | C9: 1100-1363 | D9: 长期待摊费用-Travel & entertainm projects | E9: 18001 | F9: 无形资产-专利 | G9: 无形资产 | H9: 55536.84 | I9: 57352.52 | J9: 57352.52 | K9: 57352.52 | L9: 59209.11 | M9: 59935.42 | N9: 61755.81 | O9: 63224.24 | P9: 70129.55 | Q9: 130871.74 | R9: 79205.14 | S9: 79205.14
A10: 10308 | B10: Capitalized R&D-Accumulated amortization | C10: 1110-1310 | D10: 长期待摊费用-摊销 | E10: 18101 | F10: 无形资产摊销-专利 | G10: 无形资产 | H10: =-5375410.83 -> -5375410.8 | I10: =-5707754.63 -> -5707754.6 | J10: =-6122703.26 -> -6122703.3 | K10: =-6543019.36 -> -6543019.4 | L10: =-6963335.46 -> -6963335.5 | M10: =-7383651.56 -> -7383651.6 | N10: =-7803967.66 -> -7803967.7 | O10: =-8224283.76 -> -8224283.8 | P10: =-8644599.87 -> -8644599.9 | Q10: =-9064915.97 -> -9064916 | R10: =-9485232.08 -> -9485232.1 | S10: =-9784582.89 -> -9784582.9 | U10: 长期待摊
A11: 11100 | B11: Buildings-At cost | C11: 1200-1110 | D11: 固定资产-厂房 | E11: 16301 | F11: 固定资产-动力设备 | G11: 固定资产原值 | H11: 4567986 | I11: 4567986 | J11: 4567986 | K11: 4567986 | L11: 4567986 | M11: 4567986 | N11: 4567986 | O11: 4567986 | P11: 4567986 | Q11: 4567986 | R11: 4567986 | S11: 4567986
A12: 11000 | B12: Land-At cost | C12: 1200-1120 | D12: Land | H12: 0 | I12: 0 | J12: 0 | K12: 0 | L12: 0 | M12: 0 | N12: 0 | O12: 0 | P12: 0 | Q12: 0 | R12: 0 | S12: 0
A13: 11200 | B13: Machinery & installations generic-At cost | C13: 1200-1210 | D13: 固定资产-生产设备（公用） | E13: 16300 | F13: 固定资产-机械设备 | G13: 固定资产原值 | H13: 14054523 | I13: 14070797 | J13: 14070797 | K13: 14070797 | L13: 14070797 | M13: 14070797 | N13: 14070797 | O13: 14070797 | P13: 14070797 | Q13: 14092853 | R13: 14092853 | S13: 14092853
A14: 11200 | B14: Machinery & installations generic-At cost | C14: 1200-1211 | D14: 固定资产中转科目 | H14: 0 | I14: 0 | J14: 0 | K14: 0 | L14: 0 | M14: 0 | N14: 0 | O14: 0 | P14: 0 | Q14: 0 | R14: 0 | S14: 0
A15: 11300 | B15: Machinery & installations program-At cost | C15: 1200-1310 | D15: 固定资产-生产设备（分项目） | E15: 16300 | F15: 固定资产-机械设备 | G15: 固定资产原值 | H15: 10706488 | I15: 15063720 | J15: 15063720 | K15: 15063720 | L15: 15063720 | M15: 15063720 | N15: 15063720 | O15: 15063720 | P15: 15063720 | Q15: 17221634 | R15: 17221634 | S15: 17221634
A16: 11300 | B16: Machinery & installations program-At cost | C16: 1200-1330 | D16: 固定资产-发运料架 | E16: 16300 | F16: 固定资产-机械设备 | G16: 固定资产原值 | Q16: 110987.7 | R16: 110987.7 | S16: 569987.7
A17: 11300 | B17: Machinery & installations program-At cost | C17: 1200-1340 | D17: 固定资产-料架 | E17: 16300 | F17: 固定资产-机械设备 | G17: 固定资产原值 | H17: 165440 | I17: 178440 | J17: 178440 | K17: 178440 | L17: 178440 | M17: 178440 | N17: 178440 | O17: 178440 | P17: 178440 | Q17: 178440 | R17: 178440 | S17: 178440
A18: 11300 | B18: Machinery & installations program-At cost | C18: 1200-1350 | D18: 固定资产 - Program Capex 检具 | E18: 16300 | F18: 固定资产-机械设备 | G18: 固定资产原值 | H18: 612308.4 | I18: 1023208.4 | J18: 1229424.4 | K18: 1229424.4 | L18: 1229424.4 | M18: 1229424.4 | N18: 1229424.4 | O18: 1229424.4 | P18: 1229424.4 | Q18: 1478924.4 | R18: 1478924.4 | S18: 1478924.4
A19: 11500 | B19: IT & office equipment-At cost | C19: 1200-1420 | D19: 固定资产-办公设备 | E19: 16305 | F19: 固定资产-管理用具 | G19: 固定资产原值 | H19: 1837031.4 | I19: 1837031.4 | J19: 1837031.4 | K19: 1837031.4 | L19: 1837031.4 | M19: 1837031.4 | N19: 1837031.4 | O19: 1837031.4 | P19: 1837031.4 | Q19: 1837031.4 | R19: 1837031.4 | S19: 1837031.4
A20: 11500 | B20: IT & office equipment-At cost | C20: 1200-1440 | D20: 固定资产-办公设备(软件) | E20: 16306 | F20: 固定资产-电算设备 | G20: 固定资产原值 | H20: 20700 | I20: 20700 | J20: 20700 | K20: 20700 | L20: 20700 | M20: 20700 | N20: 20700 | O20: 20700 | P20: 20700 | Q20: 20700 | R20: 20700 | S20: 20700
A21: 11500 | B21: IT & office equipment-At cost | C21: 1200-1460 | D21: 固定资产-办公设备（电脑） | E21: 16306 | F21: 固定资产-电算设备 | G21: 固定资产原值 | H21: 1746501.4 | I21: 1760871.4 | J21: 1760871.4 | K21: 1760871.4 | L21: 1760871.4 | M21: 1760871.4 | N21: 1760871.4 | O21: 1760871.4 | P21: 1760871.4 | Q21: 1760871.4 | R21: 1760871.4 | S21: 1760871.4
A22: 11700 | B22: Other tangible fixed assets-At cost | C22: 1200-1510 | D22: 固定资产-其它 | E22: 16311 | F22: 固定资产-工位器具 | G22: 固定资产原值 | H22: 1897957.3 | I22: 1897957.3 | J22: 1897957.3 | K22: 1897957.3 | L22: 1897957.3 | M22: 1897957.3 | N22: 1897957.3 | O22: 1897957.3 | P22: 1897957.3 | Q22: 1897957.3 | R22: 1897957.3 | S22: 1897957.3
A23: 11700 | B23: Other tangible fixed assets-At cost | C23: 1200-1520 | D23: 固定资产-其它 | E23: 16304 | F23: 固定资产-运输设备 | G23: 固定资产原值 | H23: 5155.2 | I23: 5155.2 | J23: 5155.2 | K23: 5155.2 | L23: 5155.2 | M23: 5155.2 | N23: 5155.2 | O23: 5155.2 | P23: 5155.2 | Q23: 5155.2 | R23: 5155.2 | S23: 5155.2
A24: 11400 | B24: Hard tools-At cost | C24: 1200-1610 | D24: 固定资产-模具 | E24: 16308 | F24: 固定资产-工装模具 | G24: 固定资产原值 | H24: =8754186-8754186+35000 -> 35000 | I24: =8798986-8798986+35000+44800 -> 79800 | J24: =10323046-8798986+35000+44800-1524060 -> 79800 | K24: =10323046-8798986+35000+44800-1524060 -> 79800 | L24: =10323046-8798986+35000+44800-1524060 -> 79800 | M24: =10323046-8798986+35000+44800-1524060 -> 79800 | N24: =10323046-8798986+35000+44800-1524060 -> 79800 | O24: =10323046-8798986+35000+44800-1524060 -> 79800 | P24: =10350131-8798986+35000+44800-1524060 -> 106885 | Q24: =10350131-8798986+35000+44800-1524060 -> 106885 | R24: =10350131-8798986+35000+44800-1524060 -> 106885 | S24: =12713331-8798986+35000+44800-1524060-2363200 -> 106885 | U24: 模具
A25: 11800 | B25: Tangible fixed assets under construction & prepayments | C25: 1200-1710 | D25: 在建工程-生产线 | E25: 16721 | F25: 在建工程 | G25: 固定资产原值 | H25: 18917943 | I25: 20609979 | J25: 20609979 | K25: 21113979 | L25: 21052479 | M25: 21042979 | N25: 21520894 | O25: 22042406 | P25: 22042406 | Q25: 22736462 | R25: 22736462 | S25: 22736462
A26: 11800 | B26: Tangible fixed assets under construction & prepayments | C26: 1200-1715 | D26: 在建工程-模具 | E26: 16721 | F26: 在建工程 | G26: 固定资产原值 | H26: 62085 | I26: 106885 | J26: 106885 | K26: 106885 | L26: 106885 | M26: 106885 | N26: 106885 | O26: 106885 | P26: 1781885 | Q26: 1781885 | R26: 1781885 | S26: =1781885-1675000 -> 106885
A27: 11800 | B27: Tangible fixed assets under construction & prepayments | C27: 1200-1720 | D27: 在建工程-检具 | E27: 16721 | F27: 在建工程 | G27: 固定资产原值 | H27: 841085.8 | I27: 854085.8 | J27: 997585.8 | K27: 997585.8 | L27: 997585.8 | M27: 997585.8 | N27: 997585.8 | O27: 997585.8 | P27: 997585.8 | Q27: 1172235.8 | R27: 1172235.8 | S27: 1172235.8
A28: 11800 | B28: Tangible fixed assets under construction & prepayments | C28: 1200-1725 | D28: 在建工程-内部和半成品料架 | E28: 16721 | F28: 在建工程 | G28: 固定资产原值 | H28: 17400 | I28: 30400 | J28: 30400 | K28: 30400 | L28: 30400 | M28: 30400 | N28: 30400 | O28: 30400 | P28: 30400 | Q28: 30400 | R28: 30400 | S28: 30400
A29: 11800 | B29: Tangible fixed assets under construction & prepayments | C29: 1200-1735 | D29: 在建工程-成品料架 | E29: 16721 | F29: 在建工程 | G29: 固定资产原值 | H29: 107053.57 | I29: 107053.57 | J29: 107053.57 | K29: 107053.57 | L29: 129553.57 | M29: 175791.27 | N29: 175791.27 | O29: 175791.27 | P29: 175791.27 | Q29: 234291.27 | R29: 360291.27 | S29: 693291.27
A30: 11800 | B30: Tangible fixed assets under construction & prepayments | C30: 1200-1740 | D30: C.I.P.-Reclasstocompleted | E30: 16721 | F30: 在建工程 | G30: 固定资产原值 | H30: -35628739 | I30: -40485314 | J30: -40691530 | K30: -40691530 | L30: -40691530 | M30: -40691530 | N30: -40691530 | O30: -40691530 | P30: -40718615 | Q30: -43259074 | R30: -43259074 | S30: -43718074
A31: 11800 | B31: Tangible fixed assets under construction & prepayments | C31: 1200-1750 | D31: Construction Land-Buildings in | E31: 16721 | F31: 在建工程 | G31: 固定资产原值 | H31: 20340928 | I31: 20340928 | J31: 20340928 | K31: 20340928 | L31: 20340928 | M31: 20340928 | N31: 20340928 | O31: 20340928 | P31: 20340928 | Q31: 20340928 | R31: 20340928 | S31: 20340928
A32: 11600 | B32: Vehicles-At cost | C32: 1200-1810 | D32: 固定资产-车辆 | E32: 16304 | F32: 固定资产-运输设备 | G32: 固定资产原值 | H32: 306358.91 | I32: 306358.91 | J32: 306358.91 | K32: 306358.91 | L32: 306358.91 | M32: 306358.91 | N32: 306358.91 | O32: 306358.91 | P32: 306358.91 | Q32: 306358.91 | R32: 306358.91 | S32: 306358.91
A33: 11108 | B33: Buildings-Accumulated depreciation | C33: 1210-1110 | D33: 累计折旧-厂房 | E33: 16401 | F33: 累计折旧-动力设备 | G33: 累计折旧 | H33: -1464815.5 | I33: -1515957.2 | J33: -1567098.9 | K33: -1618240.5 | L33: -1669382.2 | M33: -1720523.9 | N33: -1771665.5 | O33: -1822807.2 | P33: -1873948.8 | Q33: -1925090.5 | R33: -1976232.1 | S33: -2027373.8
A34: 11008 | B34: Land-Accumulated depreciation | C34: 1210-1120 | D34: Dep. Land | H34: 0 | I34: 0 | J34: 0 | K34: 0 | L34: 0 | M34: 0 | N34: 0 | O34: 0 | P34: 0 | Q34: 0 | R34: 0 | S34: 0
A35: 11208 | B35: Machinery & installations generic-Accumulated depreciation | C35: 1210-1210 | D35: 累计折旧-生产设备（公用） | E35: 16400 | F35: 累计折旧-机械设备 | G35: 累计折旧 | H35: -4683966.4 | I35: -4840307.1 | J35: -4996829.7 | K35: -5153352.4 | L35: -5309875 | M35: -5466397.7 | N35: -5622920.3 | O35: -5779443 | P35: -5935965.6 | Q35: -6092511.1 | R35: -6249270.7 | S35: -6406030.2
A36: 11308 | B36: Machinery & installations program-Accumulated depreciation | C36: 1210-1310 | D36: 累计折旧-生产设备（分项目） | E36: 16400 | F36: 累计折旧-机械设备 | G36: 累计折旧 | H36: -2816398.1 | I36: -2972000.9 | J36: -3185700 | K36: -3399399.2 | L36: -3613098.4 | M36: -3826797.5 | N36: -4040496.6 | O36: -4254195.8 | P36: -4467895 | Q36: -4681594.1 | R36: -4895293.3 | S36: -5108992.4
A37: 11308 | B37: Machinery & installations program-Accumulated depreciation | C37: 1210-1340 | D37: 累计折旧-物流器具 | E37: 16400 | F37: 累计折旧-机械设备 | G37: 累计折旧 | H37: -10026.64 | I37: -12533.3 | J37: -15213.29 | K37: -17893.28 | L37: -20573.27 | M37: -23253.26 | N37: -25933.25 | O37: -28613.25 | P37: -31293.24 | Q37: -33973.24 | R37: -36653.23 | S37: -39333.23
A38: 11308 | B38: Machinery & installations program-Accumulated depreciation | C38: 1210-1350 | D38: 累计折旧 - Program Capex 检具 | E38: 16400 | F38: 累计折旧-机械设备 | G38: 累计折旧 | H38: -136127.54 | I38: -145335.99 | J38: -162772.64 | K38: -180209.3 | L38: -197645.95 | M38: -215082.61 | N38: -232519.26 | O38: -249955.93 | P38: -267392.58 | Q38: -284829.25 | R38: -302265.9 | S38: -319702.57
A39: 11508 | B39: IT & office equipment-Accumulated depreciation | C39: 1210-1420 | D39: 累计折旧-办公设备 | E39: 16405 | F39: 累计折旧-管理用具 | G39: 累计折旧 | H39: -925877.75 | I39: -957289.96 | J39: -988701.66 | K39: -1020113.9 | L39: -1051525.6 | M39: -1082937.8 | N39: -1114349.5 | O39: -1145761.7 | P39: -1177173.4 | Q39: -1208585.6 | R39: -1239997.3 | S39: -1271409.5
A40: 11508 | B40: IT & office equipment-Accumulated depreciation | C40: 1210-1440 | D40: 累计折旧-办公设备(软件) | E40: 16406 | F40: 累计折旧-电算设备 | G40: 累计折旧 | H40: -11730 | I40: -12075 | J40: -12420 | K40: -12765 | L40: -13110 | M40: -13455 | N40: -13800 | O40: -14145 | P40: -14490 | Q40: -14835 | R40: -15180 | S40: -15525
...

Sheet 英纳法科目余额表
A1: Ledger | B1: Sub | C1: Ledger Account Description | D1: Opening Balance | E1: Transactions up to Previous Period | G1: Transactions For Current Period | I1: Closing Balance
A2: Account | E2: Debit | F2: Credit | G2: Debit | H2: Credit
A3: 1100-1310 | B3: 0 | C3: Project management | D3: 0 | E3: 0 | F3: 0 | G3: 236868.8 | H3: 236868.8 | I3: 0
A4: 1100-1311 | B4: 0 | C4: R&d investments | D4: 25048209 | E4: 3835995.2 | F4: 0 | G4: 171878.26 | H4: 4697045.7 | I4: 24359036
A5: 1100-1312 | B5: 0 | C5: Proj manag out of region-labor | D5: 4442139.2 | E5: 519372.56 | F5: 0 | G5: 17512.32 | H5: 0 | I5: 4979024.1
A6: 1100-1354 | B6: 0 | C6: Outsourced testing costs | D6: 113626.27 | E6: 0 | F6: 0 | G6: 0 | H6: 0 | I6: 113626.27
A7: 1100-1356 | B7: 0 | C7: Test electro equipment costs | D7: 28514.52 | E7: 3007.75 | F7: 0 | G7: 0 | H7: 0 | I7: 31522.27
A8: 1100-1358 | B8: 0 | C8: Pre-launchmaterials | D8: 3714227.6 | E8: 1217689.6 | F8: 959341.75 | G8: 0 | H8: 0 | I8: 3972575.5
A9: 1100-1360 | B9: 0 | C9: Pre-launchfreight | D9: 515811.71 | E9: 105079.84 | F9: 48552.01 | G9: -9822.31 | H9: 0 | I9: 562517.23
A10: 1100-1362 | B10: 0 | C10: Pre-launchother | D10: 890722.95 | E10: 313428.96 | F10: 115680.8 | G10: 13072 | H10: 13072 | I10: 1088471.1
A11: 1100-1363 | B11: 0 | C11: Travel & entertainm projects | D11: 55536.84 | E11: 87311.35 | F11: 63643.05 | G11: 0 | H11: 0 | I11: 79205.14
A12: 1110-1310 | B12: 0 | C12: Accum. amort. r&d | D12: -5043067 | E12: 282023.59 | F12: 4724188.7 | G12: 236868.8 | H12: 536219.61 | I12: -9784582.9
A13: 1200-1110 | B13: 0 | C13: Land and buildings | D13: 4567986 | E13: 0 | F13: 0 | G13: 0 | H13: 0 | I13: 4567986
A14: 1200-1210 | B14: 0 | C14: Machinery, installations gen | D14: 14054523 | E14: 38330 | F14: 0 | G14: 0 | H14: 0 | I14: 14092853
... A276: 9999-9001 | B276: 0 | C276: 3rd party inventory | D276: 0 | E276: 50439970 | F276: 50439970 | G276: 19641188 | H276: 19641188 | I276: 0
